Workbook

Sheet 개요
A1: 독도 코리아 스쿨 1.1 | B1: 실제 반영 내용
A2: 문항 수 | B2: =COUNTA(문항_KO!A2:A241) -> 240
A3: 개념 묶음 | B3: 60
A4: 단원 수 | B4: =COUNTA(단원!A2:A13) -> 12
A5: L1 알아보기 | B5: =COUNTIF(문항_KO!D2:D241,1) -> 60
A6: L2 이어보기 | B6: =COUNTIF(문항_KO!D2:D241,2) -> 60
A7: L3 자료읽기 | B7: =COUNTIF(문항_KO!D2:D241,3) -> 60
A8: L4 따져보기 | B8: =COUNTIF(문항_KO!D2:D241,4) -> 60
A9: 원본 엑셀 대조 | B9: 질문 1,513개가 원본 questions.json과 일치, 변경된 질문 0개. 진단표이지 수정 문항집은 아닙니다.
A10: 이번 파일의 범위 | B10: 새 240문항(한국어·영어 쌍)을 실제 앱에 연결. 같은 사실을 네 사고 단계로 묻는 60개 묶음입니다. 원본 1,513문항 전부를 고쳤다는 뜻이 아닙니다.
A11: 기록 보호 | B11: 새 문항 ID 910001~910240. 이전 1,513문항과 48문항의 학습 기록은 보존하며 새 출제에서는 제외합니다.
A12: 자료와 검수 | B12: 출처를 연결한 자체 검토본입니다. 독립 교사 검수·국가 교육과정 인증·실기기 검증 완료를 주장하지 않습니다.
A13: 엑셀 편집과 배포 | B13: 이 파일은 검토·편집용입니다. 엑셀을 고쳐도 웹앱이 자동 변경되지는 않습니다. tools/content의 작성 원본을 수정하고 npm run content:build 및 테스트를 실행하세요.
A14: 지도 범위 | B14: 지도 보기에는 동도의 낮고 넓은 상부를 설명하는 형상 비교도를 추가했습니다. 감상용 홈 이미지는 생성 일러스트로 유지하며, 실측 3D 지형이나 시설 위치를 재현했다고 표시하지 않습니다.

Sheet 문항_KO
A1: 문항 ID | B1: 단원 | C1: 개념 묶음 | D1: 인지단계 | E1: 질문 | F1: 보기 1 | G1: 보기 2 | H1: 보기 3 | I1: 정답 번호 | J1: 사실·해설 | K1: 오답 해설 1 | L1: 오답 해설 2 | M1: 오답 해설 3 | N1: 판단 자료 | O1: 출처 URL | P1: 질문+최장보기 글자수 | Q1: 검토 상태
A2: 910001 | B2: 1 | C2: dk-composition | D2: 1 | E2: 독도의 두 큰 섬은? | F2: 제주도와 서도 | G2: 동도와 서도 | H2: 울릉도와 동도 | I2: 2 | J2: 독도는 동도와 서도, 그리고 주변의 작은 바위섬들로 이루어져 있어요. | K2: 고른 보기 ‘제주도와 서도’와 달라요. 이 문항의 정답은 ‘동도와 서도’입니다. 독도는 동도와 서도, 그리고 주변의 작은 바위섬들로 이루어져 있어요. | L2: 독도는 동도와 서도, 그리고 주변의 작은 바위섬들로 이루어져 있어요. | M2: 고른 보기 ‘울릉도와 동도’와 달라요. 이 문항의 정답은 ‘동도와 서도’입니다. 독도는 동도와 서도, 그리고 주변의 작은 바위섬들로 이루어져 있어요. | O2: https://dokdo.mofa.go.kr/kor/introduce/location.jsp | P2: =LEN(E2)+MAX(LEN(F2),LEN(G2),LEN(H2)) -> 18 | Q2: 출처 기반 자체 검토 / 독립 승인 전
A3: 910002 | B3: 1 | C3: dk-composition | D3: 2 | E3: 동도·서도만 그리면 빠지는 것은? | F3: 주변의 작은 바위섬 | G3: 두 큰 섬의 위치 | H3: 서도라는 섬 | I3: 1 | J3: 독도는 동도와 서도, 그리고 주변의 작은 바위섬들로 이루어져 있어요. | K3: 독도는 동도와 서도, 그리고 주변의 작은 바위섬들로 이루어져 있어요. | L3: 고른 보기 ‘두 큰 섬의 위치’와 달라요. 이 문항의 정답은 ‘주변의 작은 바위섬’입니다. 독도는 동도와 서도, 그리고 주변의 작은 바위섬들로 이루어져 있어요. | M3: 고른 보기 ‘서도라는 섬’와 달라요. 이 문항의 정답은 ‘주변의 작은 바위섬’입니다. 독도는 동도와 서도, 그리고 주변의 작은 바위섬들로 이루어져 있어요. | O3: https://dokdo.mofa.go.kr/kor/introduce/location.jsp | P3: =LEN(E3)+MAX(LEN(F3),LEN(G3),LEN(H3)) -> 28 | Q3: 출처 기반 자체 검토 / 독립 승인 전
A4: 910003 | B4: 1 | C4: dk-composition | D4: 3 | E4: 자료의 89개는 무엇을 센 수일까요? | F4: 동도와 서도를 포함한 모든 섬 | G4: 동도 안에 있는 봉우리 | H4: 두 큰 섬과 별도로 센 부속 도서 | I4: 3 | J4: 독도는 동도와 서도, 그리고 주변의 작은 바위섬들로 이루어져 있어요. | K4: 고른 보기 ‘동도와 서도를 포함한 모든 섬’와 달라요. 이 문항의 정답은 ‘두 큰 섬과 별도로 센 부속 도서’입니다. 독도는 동도와 서도, 그리고 주변의 작은 바위섬들로 이루어져 있어요. | L4: 고른 보기 ‘동도 안에 있는 봉우리’와 달라요. 이 문항의 정답은 ‘두 큰 섬과 별도로 센 부속 도서’입니다. 독도는 동도와 서도, 그리고 주변의 작은 바위섬들로 이루어져 있어요. | M4: 독도는 동도와 서도, 그리고 주변의 작은 바위섬들로 이루어져 있어요. | N4: 외교부 자료: 두 큰 섬 동도·서도와 부속 도서 89개로 독도를 설명합니다. | O4: https://dokdo.mofa.go.kr/kor/introduce/location.jsp | P4: =LEN(E4)+MAX(LEN(F4),LEN(G4),LEN(H4)) -> 38 | Q4: 출처 기반 자체 검토 / 독립 승인 전
A5: 910004 | B5: 1 | C5: dk-composition | D5: 4 | E5: 독도를 ‘섬 두 개뿐’이라 소개한 글의 수정은? | F5: 89개가 모두 큰 섬이라고 고친다 | G5: 두 큰 섬과 부속 도서를 구분해 쓴다 | H5: 작은 바위섬은 모두 독도에서 뺀다 | I5: 2 | J5: 독도는 동도와 서도, 그리고 주변의 작은 바위섬들로 이루어져 있어요. 대표적인 두 섬과 독도의 전체 구성은 구분해야 합니다. | K5: 고른 보기 ‘89개가 모두 큰 섬이라고 고친다’와 달라요. 이 문항의 정답은 ‘두 큰 섬과 부속 도서를 구분해 쓴다’입니다. 독도는 동도와 서도, 그리고 주변의 작은 바위섬들로 이루어져 있어요. 대표적인 두 섬과 독도의 전체 구성은 구분해야 합니다. | L5: 독도는 동도와 서도, 그리고 주변의 작은 바위섬들로 이루어져 있어요. 대표적인 두 섬과 독도의 전체 구성은 구분해야 합니다. | M5: 고른 보기 ‘작은 바위섬은 모두 독도에서 뺀다’와 달라요. 이 문항의 정답은 ‘두 큰 섬과 부속 도서를 구분해 쓴다’입니다. 독도는 동도와 서도, 그리고 주변의 작은 바위섬들로 이루어져 있어요. 대표적인 두 섬과 독도의 전체 구성은 구분해야 합니다. | N5: 외교부 자료: 두 큰 섬 동도·서도와 부속 도서 89개로 독도를 설명합니다. | O5: https://dokdo.mofa.go.kr/kor/introduce/location.jsp | P5: =LEN(E5)+MAX(LEN(F5),LEN(G5),LEN(H5)) -> 46 | Q5: 출처 기반 자체 검토 / 독립 승인 전
A6: 910005 | B6: 1 | C6: dk-relative-location | D6: 1 | E6: 울릉도에서 독도는 어느 방향일까요? | F6: 동남쪽 | G6: 서북쪽 | H6: 남서쪽 | I6: 1 | J6: 독도는 울릉도에서 동남쪽으로 약 87.4km 떨어져 있어요. | K6: 독도는 울릉도에서 동남쪽으로 약 87.4km 떨어져 있어요. | L6: 고른 보기 ‘서북쪽’와 달라요. 이 문항의 정답은 ‘동남쪽’입니다. 독도는 울릉도에서 동남쪽으로 약 87.4km 떨어져 있어요. | M6: 고른 보기 ‘남서쪽’와 달라요. 이 문항의 정답은 ‘동남쪽’입니다. 독도는 울릉도에서 동남쪽으로 약 87.4km 떨어져 있어요. | O6: https://dokdo.mofa.go.kr/kor/introduce/location.jsp | P6: =LEN(E6)+MAX(LEN(F6),LEN(G6),LEN(H6)) -> 22 | Q6: 출처 기반 자체 검토 / 독립 승인 전
A7: 910006 | B7: 1 | C7: dk-relative-location | D7: 2 | E7: 울릉도와 독도의 관계는? | F7: 한 섬의 동쪽과 서쪽 이름 | G7: 두 섬 모두 동도 안에 있음 | H7: 바다를 사이에 둔 서로 다른 섬 | I7: 3 | J7: 독도는 울릉도에서 동남쪽으로 약 87.4km 떨어져 있어요. | K7: 고른 보기 ‘한 섬의 동쪽과 서쪽 이름’와 달라요. 이 문항의 정답은 ‘바다를 사이에 둔 서로 다른 섬’입니다. 독도는 울릉도에서 동남쪽으로 약 87.4km 떨어져 있어요. | L7: 고른 보기 ‘두 섬 모두 동도 안에 있음’와 달라요. 이 문항의 정답은 ‘바다를 사이에 둔 서로 다른 섬’입니다. 독도는 울릉도에서 동남쪽으로 약 87.4km 떨어져 있어요. | M7: 독도는 울릉도에서 동남쪽으로 약 87.4km 떨어져 있어요. | O7: https://dokdo.mofa.go.kr/kor/introduce/location.jsp | P7: =LEN(E7)+MAX(LEN(F7),LEN(G7),LEN(H7)) -> 30 | Q7: 출처 기반 자체 검토 / 독립 승인 전
A8: 910007 | B8: 1 | C8: dk-relative-location | D8: 3 | E8: 주어진 거리에서 독도에 더 가까운 곳은? | F8: 두 곳의 거리가 같음 | G8: 울릉도 | H8: 오키섬 | I8: 2 | J8: 독도는 울릉도에서 동남쪽으로 약 87.4km 떨어져 있어요. 87.4km가 157.5km보다 짧습니다. | K8: 고른 보기 ‘두 곳의 거리가 같음’와 달라요. 이 문항의 정답은 ‘울릉도’입니다. 독도는 울릉도에서 동남쪽으로 약 87.4km 떨어져 있어요. 87.4km가 157.5km보다 짧습니다. | L8: 독도는 울릉도에서 동남쪽으로 약 87.4km 떨어져 있어요. 87.4km가 157.5km보다 짧습니다. | M8: 고른 보기 ‘오키섬’와 달라요. 이 문항의 정답은 ‘울릉도’입니다. 독도는 울릉도에서 동남쪽으로 약 87.4km 떨어져 있어요. 87.4km가 157.5km보다 짧습니다. | N8: 독도 기준 거리: 울릉도 87.4km, 일본 오키섬 157.5km. 두 거리의 출발점은 모두 독도입니다. | O8: https://dokdo.mofa.go.kr/kor/introduce/location.jsp | P8: =LEN(E8)+MAX(LEN(F8),LEN(G8),LEN(H8)) -> 33 | Q8: 출처 기반 자체 검토 / 독립 승인 전
A9: 910008 | B9: 1 | C9: dk-relative-location | D9: 4 | E9: 이 거리 표만으로 뒷받침되는 말은? | F9: 울릉도가 오키섬보다 독도에 가깝다 | G9: 거리만으로 영토의 모든 역사가 결정된다 | H9: 울릉도와 독도가 육지로 이어진다 | I9: 1 | J9: 독도는 울릉도에서 동남쪽으로 약 87.4km 떨어져 있어요. 거리 비교와 역사·법적 근거의 판단은 구분합니다. | K9: 독도는 울릉도에서 동남쪽으로 약 87.4km 떨어져 있어요. 거리 비교와 역사·법적 근거의 판단은 구분합니다. | L9: 고른 보기 ‘거리만으로 영토의 모든 역사가 결정된다’와 달라요. 이 문항의 정답은 ‘울릉도가 오키섬보다 독도에 가깝다’입니다. 독도는 울릉도에서 동남쪽으로 약 87.4km 떨어져 있어요. 거리 비교와 역사·법적 근거의 판단은 구분합니다. | M9: 고른 보기 ‘울릉도와 독도가 육지로 이어진다’와 달라요. 이 문항의 정답은 ‘울릉도가 오키섬보다 독도에 가깝다’입니다. 독도는 울릉도에서 동남쪽으로 약 87.4km 떨어져 있어요. 거리 비교와 역사·법적 근거의 판단은 구분합니다. | N9: 독도 기준 거리: 울릉도 87.4km, 일본 오키섬 157.5km. 두 거리의 출발점은 모두 독도입니다. | O9: https://dokdo.mofa.go.kr/kor/introduce/location.jsp | P9: =LEN(E9)+MAX(LEN(F9),LEN(G9),LEN(H9)) -> 40 | Q9: 출처 기반 자체 검토 / 독립 승인 전
A10: 910009 | B10: 1 | C10: dk-orientation | D10: 1 | E10: 독도의 동쪽 큰 섬 이름은? | F10: 서도 | G10: 울릉도 | H10: 동도 | I10: 3 | J10: 서도는 서쪽, 동도는 동쪽의 큰 섬이에요. 지도를 돌려도 실제 동쪽과 서쪽은 바뀌지 않아요. | K10: 고른 보기 ‘서도’와 달라요. 이 문항의 정답은 ‘동도’입니다. 서도는 서쪽, 동도는 동쪽의 큰 섬이에요. 지도를 돌려도 실제 동쪽과 서쪽은 바뀌지 않아요. | L10: 고른 보기 ‘울릉도’와 달라요. 이 문항의 정답은 ‘동도’입니다. 서도는 서쪽, 동도는 동쪽의 큰 섬이에요. 지도를 돌려도 실제 동쪽과 서쪽은 바뀌지 않아요. | M10: 서도는 서쪽, 동도는 동쪽의 큰 섬이에요. 지도를 돌려도 실제 동쪽과 서쪽은 바뀌지 않아요. | O10: https://dokdo.mofa.go.kr/kor/introduce/location.jsp | P10: =LEN(E10)+MAX(LEN(F10),LEN(G10),LEN(H10)) -> 18 | Q10: 출처 기반 자체 검토 / 독립 승인 전
A11: 910010 | B11: 1 | C11: dk-orientation | D11: 2 | E11: 서도 이름의 ‘서’와 연결되는 방향은? | F11: 북쪽 | G11: 서쪽 | H11: 동쪽 | I11: 2 | J11: 서도는 서쪽, 동도는 동쪽의 큰 섬이에요. 지도를 돌려도 실제 동쪽과 서쪽은 바뀌지 않아요. | K11: 고른 보기 ‘북쪽’와 달라요. 이 문항의 정답은 ‘서쪽’입니다. 서도는 서쪽, 동도는 동쪽의 큰 섬이에요. 지도를 돌려도 실제 동쪽과 서쪽은 바뀌지 않아요. | L11: 서도는 서쪽, 동도는 동쪽의 큰 섬이에요. 지도를 돌려도 실제 동쪽과 서쪽은 바뀌지 않아요. | M11: 고른 보기 ‘동쪽’와 달라요. 이 문항의 정답은 ‘서쪽’입니다. 서도는 서쪽, 동도는 동쪽의 큰 섬이에요. 지도를 돌려도 실제 동쪽과 서쪽은 바뀌지 않아요. | O11: https://dokdo.mofa.go.kr/kor/introduce/location.jsp | P11: =LEN(E11)+MAX(LEN(F11),LEN(G11),LEN(H11)) -> 23 | Q11: 출처 기반 자체 검토 / 독립 승인 전
A12: 910011 | B12: 1 | C12: dk-orientation | D12: 3 | E12: 주어진 방향도에서 동도는 서도의 어느 쪽인가요? | F12: 오른쪽 | G12: 왼쪽 | H12: 같은 지점 | I12: 1 | J12: 서도는 서쪽, 동도는 동쪽의 큰 섬이에요. 지도를 돌려도 실제 동쪽과 서쪽은 바뀌지 않아요. | K12: 서도는 서쪽, 동도는 동쪽의 큰 섬이에요. 지도를 돌려도 실제 동쪽과 서쪽은 바뀌지 않아요. | L12: 고른 보기 ‘왼쪽’와 달라요. 이 문항의 정답은 ‘오른쪽’입니다. 서도는 서쪽, 동도는 동쪽의 큰 섬이에요. 지도를 돌려도 실제 동쪽과 서쪽은 바뀌지 않아요. | M12: 고른 보기 ‘같은 지점’와 달라요. 이 문항의 정답은 ‘오른쪽’입니다. 서도는 서쪽, 동도는 동쪽의 큰 섬이에요. 지도를 돌려도 실제 동쪽과 서쪽은 바뀌지 않아요. | N12: 방향을 익히는 개략도: 북쪽 ↑, 서쪽 ←, 동쪽 →. 서도가 왼쪽, 동도가 오른쪽에 있습니다. 두 섬의 해안선이나 정확한 거리를 나타내는 도면은 아닙니다. | O12: https://dokdo.mofa.go.kr/kor/introduce/location.jsp | P12: =LEN(E12)+MAX(LEN(F12),LEN(G12),LEN(H12)) -> 31 | Q12: 출처 기반 자체 검토 / 독립 승인 전
A13: 910012 | B13: 1 | C13: dk-orientation | D13: 4 | E13: 지도를 돌려 동도가 왼쪽에 보이면? | F13: 동도의 이름을 서도로 바꾼다 | G13: 섬이 실제로 이동했다고 판단한다 | H13: 방향표로 실제 동서 관계를 확인한다 | I13: 3 | J13: 서도는 서쪽, 동도는 동쪽의 큰 섬이에요. 지도를 돌려도 실제 동쪽과 서쪽은 바뀌지 않아요. 화면의 좌우와 지리적 동서는 다를 수 있습니다. | K13: 고른 보기 ‘동도의 이름을 서도로 바꾼다’와 달라요. 이 문항의 정답은 ‘방향표로 실제 동서 관계를 확인한다’입니다. 서도는 서쪽, 동도는 동쪽의 큰 섬이에요. 지도를 돌려도 실제 동쪽과 서쪽은 바뀌지 않아요. 화면의 좌우와 지리적 동서는 다를 수 있습니다. | L13: 고른 보기 ‘섬이 실제로 이동했다고 판단한다’와 달라요. 이 문항의 정답은 ‘방향표로 실제 동서 관계를 확인한다’입니다. 서도는 서쪽, 동도는 동쪽의 큰 섬이에요. 지도를 돌려도 실제 동쪽과 서쪽은 바뀌지 않아요. 화면의 좌우와 지리적 동서는 다를 수 있습니다. | M13: 서도는 서쪽, 동도는 동쪽의 큰 섬이에요. 지도를 돌려도 실제 동쪽과 서쪽은 바뀌지 않아요. 화면의 좌우와 지리적 동서는 다를 수 있습니다. | N13: 방향을 익히는 개략도: 북쪽 ↑, 서쪽 ←, 동쪽 →. 서도가 왼쪽, 동도가 오른쪽에 있습니다. 두 섬의 해안선이나 정확한 거리를 나타내는 도면은 아닙니다. | O13: https://dokdo.mofa.go.kr/kor/introduce/location.jsp | P13: =LEN(E13)+MAX(LEN(F13),LEN(G13),LEN(H13)) -> 38 | Q13: 출처 기반 자체 검토 / 독립 승인 전
A14: 910013 | B14: 1 | C14: dk-visibility | D14: 1 | E14: 울릉도에서 독도를 보기 좋은 날씨는? | F14: 시야를 가리는 비 | G14: 맑은 날 | H14: 짙은 안개 | I14: 2 | J14: 울릉도에서는 맑은 날 독도를 볼 수 있어요. 안개나 비가 시야를 가리면 보이지 않을 수도 있어요. | K14: 고른 보기 ‘시야를 가리는 비’와 달라요. 이 문항의 정답은 ‘맑은 날’입니다. 울릉도에서는 맑은 날 독도를 볼 수 있어요. 안개나 비가 시야를 가리면 보이지 않을 수도 있어요. | L14: 울릉도에서는 맑은 날 독도를 볼 수 있어요. 안개나 비가 시야를 가리면 보이지 않을 수도 있어요. | M14: 고른 보기 ‘짙은 안개’와 달라요. 이 문항의 정답은 ‘맑은 날’입니다. 울릉도에서는 맑은 날 독도를 볼 수 있어요. 안개나 비가 시야를 가리면 보이지 않을 수도 있어요. | O14: https://dokdo.mofa.go.kr/kor/introduce/location.jsp https://dokdo.mofa.go.kr/kor/pds/part06_view02.jsp | P14: =LEN(E14)+MAX(LEN(F14),LEN(G14),LEN(H14)) -> 29 | Q14: 출처 기반 자체 검토 / 독립 승인 전
A15: 910014 | B15: 1 | C15: dk-visibility | D15: 2 | E15: 오늘 독도가 안 보이면 먼저 살필 것은? | F15: 안개 같은 날씨 조건 | G15: 섬 이름의 변경 | H15: 서도의 면적 증가 | I15: 1 | J15: 울릉도에서는 맑은 날 독도를 볼 수 있어요. 안개나 비가 시야를 가리면 보이지 않을 수도 있어요. | K15: 울릉도에서는 맑은 날 독도를 볼 수 있어요. 안개나 비가 시야를 가리면 보이지 않을 수도 있어요. | L15: 고른 보기 ‘섬 이름의 변경’와 달라요. 이 문항의 정답은 ‘안개 같은 날씨 조건’입니다. 울릉도에서는 맑은 날 독도를 볼 수 있어요. 안개나 비가 시야를 가리면 보이지 않을 수도 있어요. | M15: 고른 보기 ‘서도의 면적 증가’와 달라요. 이 문항의 정답은 ‘안개 같은 날씨 조건’입니다. 울릉도에서는 맑은 날 독도를 볼 수 있어요. 안개나 비가 시야를 가리면 보이지 않을 수도 있어요. | O15: https://dokdo.mofa.go.kr/kor/introduce/location.jsp https://dokdo.mofa.go.kr/kor/pds/part06_view02.jsp | P15: =LEN(E15)+MAX(LEN(F15),LEN(G15),LEN(H15)) -> 33 | Q15: 출처 기반 자체 검토 / 독립 승인 전
A16: 910015 | B16: 1 | C16: dk-visibility | D16: 3 | E16: 옛 기록이 가시성에 붙인 조건은? | F16: 모든 날씨에 항상 | G16: 겨울에만 | H16: 날씨가 맑을 때 | I16: 3 | J16: 울릉도에서는 맑은 날 독도를 볼 수 있어요. 안개나 비가 시야를 가리면 보이지 않을 수도 있어요. | K16: 고른 보기 ‘모든 날씨에 항상’와 달라요. 이 문항의 정답은 ‘날씨가 맑을 때’입니다. 울릉도에서는 맑은 날 독도를 볼 수 있어요. 안개나 비가 시야를 가리면 보이지 않을 수도 있어요. | L16: 고른 보기 ‘겨울에만’와 달라요. 이 문항의 정답은 ‘날씨가 맑을 때’입니다. 울릉도에서는 맑은 날 독도를 볼 수 있어요. 안개나 비가 시야를 가리면 보이지 않을 수도 있어요. | M16: 울릉도에서는 맑은 날 독도를 볼 수 있어요. 안개나 비가 시야를 가리면 보이지 않을 수도 있어요. | N16: 외교부가 소개한 『세종실록』 지리지는 우산·무릉 두 섬이 서로 멀지 않아 날씨가 맑으면 바라볼 수 있다고 설명합니다. | O16: https://dokdo.mofa.go.kr/kor/introduce/location.jsp https://dokdo.mofa.go.kr/kor/pds/part06_view02.jsp | P16: =LEN(E16)+MAX(LEN(F16),LEN(G16),LEN(H16)) -> 27 | Q16: 출처 기반 자체 검토 / 독립 승인 전
A17: 910016 | B17: 1 | C17: dk-visibility | D17: 4 | E17: ‘울릉도에서 독도는 항상 보인다’는 요약은? | F17: 가까운 섬에는 날씨가 영향을 주지 않는다 | G17: 맑은 날이라는 조건이 빠져 부정확하다 | H17: 섬 이름이 맞으므로 충분히 정확하다 | I17: 2 | J17: 울릉도에서는 맑은 날 독도를 볼 수 있어요. 안개나 비가 시야를 가리면 보이지 않을 수도 있어요. | K17: 고른 보기 ‘가까운 섬에는 날씨가 영향을 주지 않는다’와 달라요. 이 문항의 정답은 ‘맑은 날이라는 조건이 빠져 부정확하다’입니다. 울릉도에서는 맑은 날 독도를 볼 수 있어요. 안개나 비가 시야를 가리면 보이지 않을 수도 있어요. | L17: 울릉도에서는 맑은 날 독도를 볼 수 있어요. 안개나 비가 시야를 가리면 보이지 않을 수도 있어요. | M17: 고른 보기 ‘섬 이름이 맞으므로 충분히 정확하다’와 달라요. 이 문항의 정답은 ‘맑은 날이라는 조건이 빠져 부정확하다’입니다. 울릉도에서는 맑은 날 독도를 볼 수 있어요. 안개나 비가 시야를 가리면 보이지 않을 수도 있어요. | N17: 외교부가 소개한 『세종실록』 지리지는 우산·무릉 두 섬이 서로 멀지 않아 날씨가 맑으면 바라볼 수 있다고 설명합니다. | O17: https://dokdo.mofa.go.kr/kor/introduce/location.jsp https://dokdo.mofa.go.kr/kor/pds/part06_view02.jsp | P17: =LEN(E17)+MAX(LEN(F17),LEN(G17),LEN(H17)) -> 46 | Q17: 출처 기반 자체 검토 / 독립 승인 전
A18: 910017 | B18: 1 | C18: dk-islet-count | D18: 1 | E18: 작은 바위섬도 독도의 일부일까요? | F18: 네, 독도의 일부예요 | G18: 아니요, 큰 섬만 독도예요 | H18: 모두 울릉도의 일부예요 | I18: 1 | J18: 독도 전체 면적에는 동도·서도뿐 아니라 부속 도서의 땅도 포함돼요. | K18: 독도 전체 면적에는 동도·서도뿐 아니라 부속 도서의 땅도 포함돼요. | L18: 고른 보기 ‘아니요, 큰 섬만 독도예요’와 달라요. 이 문항의 정답은 ‘네, 독도의 일부예요’입니다. 독도 전체 면적에는 동도·서도뿐 아니라 부속 도서의 땅도 포함돼요. | M18: 고른 보기 ‘모두 울릉도의 일부예요’와 달라요. 이 문항의 정답은 ‘네, 독도의 일부예요’입니다. 독도 전체 면적에는 동도·서도뿐 아니라 부속 도서의 땅도 포함돼요. | O18: https://dokdo.mofa.go.kr/kor/introduce/location.jsp | P18: =LEN(E18)+MAX(LEN(F18),LEN(G18),LEN(H18)) -> 32 | Q18: 출처 기반 자체 검토 / 독립 승인 전
A19: 910018 | B19: 1 | C19: dk-islet-count | D19: 2 | E19: 독도 전체 넓이를 구할 때 더할 것은? | F19: 두 큰 섬의 높이 | G19: 울릉도 전체 넓이 | H19: 두 큰 섬과 부속 도서의 넓이 | I19: 3 | J19: 독도 전체 면적에는 동도·서도뿐 아니라 부속 도서의 땅도 포함돼요. | K19: 고른 보기 ‘두 큰 섬의 높이’와 달라요. 이 문항의 정답은 ‘두 큰 섬과 부속 도서의 넓이’입니다. 독도 전체 면적에는 동도·서도뿐 아니라 부속 도서의 땅도 포함돼요. | L19: 고른 보기 ‘울릉도 전체 넓이’와 달라요. 이 문항의 정답은 ‘두 큰 섬과 부속 도서의 넓이’입니다. 독도 전체 면적에는 동도·서도뿐 아니라 부속 도서의 땅도 포함돼요. | M19: 독도 전체 면적에는 동도·서도뿐 아니라 부속 도서의 땅도 포함돼요. | O19: https://dokdo.mofa.go.kr/kor/introduce/location.jsp | P19: =LEN(E19)+MAX(LEN(F19),LEN(G19),LEN(H19)) -> 37 | Q19: 출처 기반 자체 검토 / 독립 승인 전
A20: 910019 | B20: 1 | C20: dk-islet-count | D20: 3 | E20: 두 큰 섬의 면적 합이 전체보다 작은 까닭은? | F20: 섬의 높이가 면적에서 빠졌기 때문 | G20: 부속 도서 면적이 따로 있기 때문 | H20: 바다 넓이를 두 배로 계산했기 때문 | I20: 2 | J20: 독도 전체 면적에는 동도·서도뿐 아니라 부속 도서의 땅도 포함돼요. | K20: 고른 보기 ‘섬의 높이가 면적에서 빠졌기 때문’와 달라요. 이 문항의 정답은 ‘부속 도서 면적이 따로 있기 때문’입니다. 독도 전체 면적에는 동도·서도뿐 아니라 부속 도서의 땅도 포함돼요. | L20: 독도 전체 면적에는 동도·서도뿐 아니라 부속 도서의 땅도 포함돼요. | M20: 고른 보기 ‘바다 넓이를 두 배로 계산했기 때문’와 달라요. 이 문항의 정답은 ‘부속 도서 면적이 따로 있기 때문’입니다. 독도 전체 면적에는 동도·서도뿐 아니라 부속 도서의 땅도 포함돼요. | N20: 면적 자료: 동도 73,297㎡, 서도 88,740㎡, 독도 전체 187,554㎡. 전체에는 부속 도서가 포함됩니다. | O20: https://dokdo.mofa.go.kr/kor/introduce/location.jsp | P20: =LEN(E20)+MAX(LEN(F20),LEN(G20),LEN(H20)) -> 44 | Q20: 출처 기반 자체 검토 / 독립 승인 전
A21: 910020 | B21: 1 | C21: dk-islet-count | D21: 4 | E21: 사진 한 장에 보이는 바위 수를 전체 수라 한다면? | F21: 사진 밖의 부속 도서를 빠뜨릴 수 있다 | G21: 사진의 바위는 모두 독도가 아니다 | H21: 사진이면 반드시 전체를 보여준다 | I21: 1 | J21: 독도 전체 면적에는 동도·서도뿐 아니라 부속 도서의 땅도 포함돼요. | K21: 독도 전체 면적에는 동도·서도뿐 아니라 부속 도서의 땅도 포함돼요. | L21: 고른 보기 ‘사진의 바위는 모두 독도가 아니다’와 달라요. 이 문항의 정답은 ‘사진 밖의 부속 도서를 빠뜨릴 수 있다’입니다. 독도 전체 면적에는 동도·서도뿐 아니라 부속 도서의 땅도 포함돼요. | M21: 고른 보기 ‘사진이면 반드시 전체를 보여준다’와 달라요. 이 문항의 정답은 ‘사진 밖의 부속 도서를 빠뜨릴 수 있다’입니다. 독도 전체 면적에는 동도·서도뿐 아니라 부속 도서의 땅도 포함돼요. | N21: 면적 자료: 동도 73,297㎡, 서도 88,740㎡, 독도 전체 187,554㎡. 전체에는 부속 도서가 포함됩니다. | O21: https://dokdo.mofa.go.kr/kor/introduce/location.jsp | P21: =LEN(E21)+MAX(LEN(F21),LEN(G21),LEN(H21)) -> 49 | Q21: 출처 기반 자체 검토 / 독립 승인 전
A22: 910021 | B22: 2 | C22: dk-heights | D22: 1 | E22: 두 큰 섬 중 더 높은 섬은? | F22: 동도 | G22: 두 섬이 같아요 | H22: 서도 | I22: 3 | J22: 서도의 최고 높이는 168.5m, 동도는 98.6m예요. 서도가 더 높아요. | K22: 고른 보기 ‘동도’와 달라요. 이 문항의 정답은 ‘서도’입니다. 서도의 최고 높이는 168.5m, 동도는 98.6m예요. 서도가 더 높아요. | L22: 고른 보기 ‘두 섬이 같아요’와 달라요. 이 문항의 정답은 ‘서도’입니다. 서도의 최고 높이는 168.5m, 동도는 98.6m예요. 서도가 더 높아요. | M22: 서도의 최고 높이는 168.5m, 동도는 98.6m예요. 서도가 더 높아요. | O22: https://dokdo.mofa.go.kr/kor/introduce/location.jsp | P22: =LEN(E22)+MAX(LEN(F22),LEN(G22),LEN(H22)) -> 24 | Q22: 출처 기반 자체 검토 / 독립 승인 전
A23: 910022 | B23: 2 | C23: dk-heights | D23: 2 | E23: 높이를 바르게 연결한 것은? | F23: 두 섬 모두 168.5m | G23: 서도 168.5m·동도 98.6m | H23: 서도 98.6m·동도 168.5m | I23: 2 | J23: 서도의 최고 높이는 168.5m, 동도는 98.6m예요. 서도가 더 높아요. | K23: 고른 보기 ‘두 섬 모두 168.5m’와 달라요. 이 문항의 정답은 ‘서도 168.5m·동도 98.6m’입니다. 서도의 최고 높이는 168.5m, 동도는 98.6m예요. 서도가 더 높아요. | L23: 서도의 최고 높이는 168.5m, 동도는 98.6m예요. 서도가 더 높아요. | M23: 고른 보기 ‘서도 98.6m·동도 168.5m’와 달라요. 이 문항의 정답은 ‘서도 168.5m·동도 98.6m’입니다. 서도의 최고 높이는 168.5m, 동도는 98.6m예요. 서도가 더 높아요. | O23: https://dokdo.mofa.go.kr/kor/introduce/location.jsp | P23: =LEN(E23)+MAX(LEN(F23),LEN(G23),LEN(H23)) -> 33 | Q23: 출처 기반 자체 검토 / 독립 승인 전
A24: 910023 | B24: 2 | C24: dk-heights | D24: 3 | E24: 자료에서 최고 높이의 차이는? | F24: 69.9m | G24: 267.1m | H24: 87.4m | I24: 1 | J24: 서도의 최고 높이는 168.5m, 동도는 98.6m예요. 서도가 더 높아요. 168.5−98.6=69.9m입니다. 더하기가 아니라 차이를 구합니다. | K24: 서도의 최고 높이는 168.5m, 동도는 98.6m예요. 서도가 더 높아요. 168.5−98.6=69.9m입니다. 더하기가 아니라 차이를 구합니다. | L24: 고른 보기 ‘267.1m’와 달라요. 이 문항의 정답은 ‘69.9m’입니다. 서도의 최고 높이는 168.5m, 동도는 98.6m예요. 서도가 더 높아요. 168.5−98.6=69.9m입니다. 더하기가 아니라 차이를 구합니다. | M24: 고른 보기 ‘87.4m’와 달라요. 이 문항의 정답은 ‘69.9m’입니다. 서도의 최고 높이는 168.5m, 동도는 98.6m예요. 서도가 더 높아요. 168.5−98.6=69.9m입니다. 더하기가 아니라 차이를 구합니다. | N24: 높이 자료: 서도 168.5m / 동도 98.6m. 두 값 모두 해수면을 기준으로 한 높이입니다. | O24: https://dokdo.mofa.go.kr/kor/introduce/location.jsp | P24: =LEN(E24)+MAX(LEN(F24),LEN(G24),LEN(H24)) -> 22 | Q24: 출처 기반 자체 검토 / 독립 승인 전
A25: 910024 | B25: 2 | C25: dk-heights | D25: 4 | E25: 사진 속 동도가 더 커 보일 때 옳은 판단은? | F25: 사진 크기만으로 동도가 더 높다고 한다 | G25: 사진마다 실제 표고가 달라진다고 한다 | H25: 원근과 실제 높이 자료를 함께 살핀다 | I25: 3 | J25: 서도의 최고 높이는 168.5m, 동도는 98.6m예요. 서도가 더 높아요. | K25: 고른 보기 ‘사진 크기만으로 동도가 더 높다고 한다’와 달라요. 이 문항의 정답은 ‘원근과 실제 높이 자료를 함께 살핀다’입니다. 서도의 최고 높이는 168.5m, 동도는 98.6m예요. 서도가 더 높아요. | L25: 고른 보기 ‘사진마다 실제 표고가 달라진다고 한다’와 달라요. 이 문항의 정답은 ‘원근과 실제 높이 자료를 함께 살핀다’입니다. 서도의 최고 높이는 168.5m, 동도는 98.6m예요. 서도가 더 높아요. | M25: 서도의 최고 높이는 168.5m, 동도는 98.6m예요. 서도가 더 높아요. | N25: 높이 자료: 서도 168.5m / 동도 98.6m. 두 값 모두 해수면을 기준으로 한 높이입니다. | O25: https://dokdo.mofa.go.kr/kor/introduce/location.jsp | P25: =LEN(E25)+MAX(LEN(F25),LEN(G25),LEN(H25)) -> 46 | Q25: 출처 기반 자체 검토 / 독립 승인 전
A26: 910025 | B26: 2 | C26: dk-area | D26: 1 | E26: 땅의 넓이가 더 넓은 큰 섬은? | F26: 두 섬이 같아요 | G26: 서도 | H26: 동도 | I26: 2 | J26: 서도는 동도보다 땅의 넓이도 넓어요. 높이와 면적은 서로 다른 값이에요. | K26: 고른 보기 ‘두 섬이 같아요’와 달라요. 이 문항의 정답은 ‘서도’입니다. 서도는 동도보다 땅의 넓이도 넓어요. 높이와 면적은 서로 다른 값이에요. | L26: 서도는 동도보다 땅의 넓이도 넓어요. 높이와 면적은 서로 다른 값이에요. | M26: 고른 보기 ‘동도’와 달라요. 이 문항의 정답은 ‘서도’입니다. 서도는 동도보다 땅의 넓이도 넓어요. 높이와 면적은 서로 다른 값이에요. | O26: https://dokdo.mofa.go.kr/kor/introduce/location.jsp | P26: =LEN(E26)+MAX(LEN(F26),LEN(G26),LEN(H26)) -> 25 | Q26: 출처 기반 자체 검토 / 독립 승인 전
A27: 910026 | B27: 2 | C27: dk-area | D27: 2 | E27: ‘서도가 더 넓다’는 무엇을 비교한 말인가요? | F27: 땅의 넓이 | G27: 바다의 깊이 | H27: 등대의 높이 | I27: 1 | J27: 서도는 동도보다 땅의 넓이도 넓어요. 높이와 면적은 서로 다른 값이에요. | K27: 서도는 동도보다 땅의 넓이도 넓어요. 높이와 면적은 서로 다른 값이에요. | L27: 고른 보기 ‘바다의 깊이’와 달라요. 이 문항의 정답은 ‘땅의 넓이’입니다. 서도는 동도보다 땅의 넓이도 넓어요. 높이와 면적은 서로 다른 값이에요. | M27: 고른 보기 ‘등대의 높이’와 달라요. 이 문항의 정답은 ‘땅의 넓이’입니다. 서도는 동도보다 땅의 넓이도 넓어요. 높이와 면적은 서로 다른 값이에요. | O27: https://dokdo.mofa.go.kr/kor/introduce/location.jsp | P27: =LEN(E27)+MAX(LEN(F27),LEN(G27),LEN(H27)) -> 31 | Q27: 출처 기반 자체 검토 / 독립 승인 전
A28: 910027 | B28: 2 | C28: dk-area | D28: 3 | E28: 두 섬의 면적을 비교할 때 사용할 값은? | F28: 168.5m와 98.6m | G28: 87.4km와 151m | H28: 88,740㎡와 73,297㎡ | I28: 3 | J28: 서도는 동도보다 땅의 넓이도 넓어요. 높이와 면적은 서로 다른 값이에요. | K28: 고른 보기 ‘168.5m와 98.6m’와 달라요. 이 문항의 정답은 ‘88,740㎡와 73,297㎡’입니다. 서도는 동도보다 땅의 넓이도 넓어요. 높이와 면적은 서로 다른 값이에요. | L28: 고른 보기 ‘87.4km와 151m’와 달라요. 이 문항의 정답은 ‘88,740㎡와 73,297㎡’입니다. 서도는 동도보다 땅의 넓이도 넓어요. 높이와 면적은 서로 다른 값이에요. | M28: 서도는 동도보다 땅의 넓이도 넓어요. 높이와 면적은 서로 다른 값이에요. | N28: 서도 면적 88,740㎡, 동도 면적 73,297㎡. 높이는 m, 면적은 ㎡로 표시합니다. | O28: https://dokdo.mofa.go.kr/kor/introduce/location.jsp | P28: =LEN(E28)+MAX(LEN(F28),LEN(G28),LEN(H28)) -> 38 | Q28: 출처 기반 자체 검토 / 독립 승인 전
A29: 910028 | B29: 2 | C29: dk-area | D29: 4 | E29: ‘서도는 높으니 반드시 넓다’라는 설명은? | F29: 높은 섬은 언제나 면적이 작다 | G29: 면적은 별도의 면적 자료로 확인해야 한다 | H29: 높이를 더하면 면적이 되므로 옳다 | I29: 2 | J29: 서도는 동도보다 땅의 넓이도 넓어요. 높이와 면적은 서로 다른 값이에요. 이번 경우 두 값 모두 서도가 크지만, 높이만으로 면적을 증명할 수는 없습니다. | K29: 고른 보기 ‘높은 섬은 언제나 면적이 작다’와 달라요. 이 문항의 정답은 ‘면적은 별도의 면적 자료로 확인해야 한다’입니다. 서도는 동도보다 땅의 넓이도 넓어요. 높이와 면적은 서로 다른 값이에요. 이번 경우 두 값 모두 서도가 크지만, 높이만으로 면적을 증명할 수는 없습니다. | L29: 서도는 동도보다 땅의 넓이도 넓어요. 높이와 면적은 서로 다른 값이에요. 이번 경우 두 값 모두 서도가 크지만, 높이만으로 면적을 증명할 수는 없습니다. | M29: 고른 보기 ‘높이를 더하면 면적이 되므로 옳다’와 달라요. 이 문항의 정답은 ‘면적은 별도의 면적 자료로 확인해야 한다’입니다. 서도는 동도보다 땅의 넓이도 넓어요. 높이와 면적은 서로 다른 값이에요. 이번 경우 두 값 모두 서도가 크지만, 높이만으로 면적을 증명할 수는 없습니다. | N29: 서도 면적 88,740㎡, 동도 면적 73,297㎡. 높이는 m, 면적은 ㎡로 표시합니다. | O29: https://dokdo.mofa.go.kr/kor/introduce/location.jsp | P29: =LEN(E29)+MAX(LEN(F29),LEN(G29),LEN(H29)) -> 45 | Q29: 출처 기반 자체 검토 / 독립 승인 전
A30: 910029 | B30: 2 | C30: dk-shore-gap | D30: 1 | E30: 동도와 서도 사이를 채우는 것은? | F30: 바닷물 | G30: 두 섬을 잇는 육지 | H30: 울릉도의 산 | I30: 1 | J30: 동도와 서도는 바다로 떨어져 있어요. 가장 가까운 해안 사이 거리는 약 151m예요. | K30: 동도와 서도는 바다로 떨어져 있어요. 가장 가까운 해안 사이 거리는 약 151m예요. | L30: 고른 보기 ‘두 섬을 잇는 육지’와 달라요. 이 문항의 정답은 ‘바닷물’입니다. 동도와 서도는 바다로 떨어져 있어요. 가장 가까운 해안 사이 거리는 약 151m예요. | M30: 고른 보기 ‘울릉도의 산’와 달라요. 이 문항의 정답은 ‘바닷물’입니다. 동도와 서도는 바다로 떨어져 있어요. 가장 가까운 해안 사이 거리는 약 151m예요. | O30: https://www.dokdo.re.kr/home/cms/cmsCont.do?cntnts_sn=66 | P30: =LEN(E30)+MAX(LEN(F30),LEN(G30),LEN(H30)) -> 28 | Q30: 출처 기반 자체 검토 / 독립 승인 전
A31: 910030 | B31: 2 | C31: dk-shore-gap | D31: 2 | E31: 151m와 바르게 연결되는 것은? | F31: 서도의 최고 높이 | G31: 울릉도에서 독도까지 거리 | H31: 가장 가까운 해안 사이 거리 | I31: 3 | J31: 동도와 서도는 바다로 떨어져 있어요. 가장 가까운 해안 사이 거리는 약 151m예요. | K31: 고른 보기 ‘서도의 최고 높이’와 달라요. 이 문항의 정답은 ‘가장 가까운 해안 사이 거리’입니다. 동도와 서도는 바다로 떨어져 있어요. 가장 가까운 해안 사이 거리는 약 151m예요. | L31: 고른 보기 ‘울릉도에서 독도까지 거리’와 달라요. 이 문항의 정답은 ‘가장 가까운 해안 사이 거리’입니다. 동도와 서도는 바다로 떨어져 있어요. 가장 가까운 해안 사이 거리는 약 151m예요. | M31: 동도와 서도는 바다로 떨어져 있어요. 가장 가까운 해안 사이 거리는 약 151m예요. | O31: https://www.dokdo.re.kr/home/cms/cmsCont.do?cntnts_sn=66 | P31: =LEN(E31)+MAX(LEN(F31),LEN(G31),LEN(H31)) -> 33 | Q31: 출처 기반 자체 검토 / 독립 승인 전
A32: 910031 | B32: 2 | C32: dk-shore-gap | D32: 3 | E32: 151m 선을 그릴 때 맞는 두 끝점은? | F32: 울릉도와 서도의 중심 | G32: 두 섬의 가장 가까운 해안 지점 | H32: 동도와 서도의 정상 | I32: 2 | J32: 동도와 서도는 바다로 떨어져 있어요. 가장 가까운 해안 사이 거리는 약 151m예요. | K32: 고른 보기 ‘울릉도와 서도의 중심’와 달라요. 이 문항의 정답은 ‘두 섬의 가장 가까운 해안 지점’입니다. 동도와 서도는 바다로 떨어져 있어요. 가장 가까운 해안 사이 거리는 약 151m예요. | L32: 동도와 서도는 바다로 떨어져 있어요. 가장 가까운 해안 사이 거리는 약 151m예요. | M32: 고른 보기 ‘동도와 서도의 정상’와 달라요. 이 문항의 정답은 ‘두 섬의 가장 가까운 해안 지점’입니다. 동도와 서도는 바다로 떨어져 있어요. 가장 가까운 해안 사이 거리는 약 151m예요. | N32: 지형 자료의 151m는 두 섬 사이 해협의 폭을 뜻합니다. 두 정상이나 두 섬 중심 사이의 거리가 아닙니다. | O32: https://www.dokdo.re.kr/home/cms/cmsCont.do?cntnts_sn=66 | P32: =LEN(E32)+MAX(LEN(F32),LEN(G32),LEN(H32)) -> 39 | Q32: 출처 기반 자체 검토 / 독립 승인 전
A33: 910032 | B33: 2 | C33: dk-shore-gap | D33: 4 | E33: 정상끼리 잇는 선에 151m를 썼다면? | F33: 자료와 측정 끝점이 달라 수정한다 | G33: 같은 두 섬이므로 어디든 괜찮다 | H33: 151m는 면적이므로 선을 지운다 | I33: 1 | J33: 동도와 서도는 바다로 떨어져 있어요. 가장 가까운 해안 사이 거리는 약 151m예요. 숫자뿐 아니라 무엇과 무엇 사이를 재는지도 맞아야 합니다. | K33: 동도와 서도는 바다로 떨어져 있어요. 가장 가까운 해안 사이 거리는 약 151m예요. 숫자뿐 아니라 무엇과 무엇 사이를 재는지도 맞아야 합니다. | L33: 고른 보기 ‘같은 두 섬이므로 어디든 괜찮다’와 달라요. 이 문항의 정답은 ‘자료와 측정 끝점이 달라 수정한다’입니다. 동도와 서도는 바다로 떨어져 있어요. 가장 가까운 해안 사이 거리는 약 151m예요. 숫자뿐 아니라 무엇과 무엇 사이를 재는지도 맞아야 합니다. | M33: 고른 보기 ‘151m는 면적이므로 선을 지운다’와 달라요. 이 문항의 정답은 ‘자료와 측정 끝점이 달라 수정한다’입니다. 동도와 서도는 바다로 떨어져 있어요. 가장 가까운 해안 사이 거리는 약 151m예요. 숫자뿐 아니라 무엇과 무엇 사이를 재는지도 맞아야 합니다. | N33: 지형 자료의 151m는 두 섬 사이 해협의 폭을 뜻합니다. 두 정상이나 두 섬 중심 사이의 거리가 아닙니다. | O33: https://www.dokdo.re.kr/home/cms/cmsCont.do?cntnts_sn=66 | P33: =LEN(E33)+MAX(LEN(F33),LEN(G33),LEN(H33)) -> 39 | Q33: 출처 기반 자체 검토 / 독립 승인 전
A34: 910033 | B34: 2 | C34: dk-terrain-contrast | D34: 1 | E34: 가파르게 솟은 모습이 두드러지는 섬은? | F34: 동도 | G34: 두 섬 모두 평평해요 | H34: 서도 | I34: 3 | J34: 서도는 가파르게 솟은 모습이고, 동도는 정상 부근에 비교적 완만한 공간이 있어요. | K34: 고른 보기 ‘동도’와 달라요. 이 문항의 정답은 ‘서도’입니다. 서도는 가파르게 솟은 모습이고, 동도는 정상 부근에 비교적 완만한 공간이 있어요. | L34: 고른 보기 ‘두 섬 모두 평평해요’와 달라요. 이 문항의 정답은 ‘서도’입니다. 서도는 가파르게 솟은 모습이고, 동도는 정상 부근에 비교적 완만한 공간이 있어요. | M34: 서도는 가파르게 솟은 모습이고, 동도는 정상 부근에 비교적 완만한 공간이 있어요. | O34: https://www.heritage.go.kr/heri/cul/culSelectDetail.do?VdkVgwKey=16%2C03360000%2C37&pageNo=1_1_2_0 https://www.jbe.go.kr/dokdo/assets/sub/picture.html | P34: =LEN(E34)+MAX(LEN(F34),LEN(G34),LEN(H34)) -> 32 | Q34: 출처 기반 자체 검토 / 독립 승인 전
A35: 910034 | B35: 2 | C35: dk-terrain-contrast | D35: 2 | E35: 동도 정상 부근과 연결되는 모습은? | F35: 섬 전체가 모래평지 | G35: 비교적 완만한 공간 | H35: 서도보다 높은 뾰족봉만 | I35: 2 | J35: 서도는 가파르게 솟은 모습이고, 동도는 정상 부근에 비교적 완만한 공간이 있어요. | K35: 고른 보기 ‘섬 전체가 모래평지’와 달라요. 이 문항의 정답은 ‘비교적 완만한 공간’입니다. 서도는 가파르게 솟은 모습이고, 동도는 정상 부근에 비교적 완만한 공간이 있어요. | L35: 서도는 가파르게 솟은 모습이고, 동도는 정상 부근에 비교적 완만한 공간이 있어요. | M35: 고른 보기 ‘서도보다 높은 뾰족봉만’와 달라요. 이 문항의 정답은 ‘비교적 완만한 공간’입니다. 서도는 가파르게 솟은 모습이고, 동도는 정상 부근에 비교적 완만한 공간이 있어요. | O35: https://www.heritage.go.kr/heri/cul/culSelectDetail.do?VdkVgwKey=16%2C03360000%2C37&pageNo=1_1_2_0 https://www.jbe.go.kr/dokdo/assets/sub/picture.html | P35: =LEN(E35)+MAX(LEN(F35),LEN(G35),LEN(H35)) -> 31 | Q35: 출처 기반 자체 검토 / 독립 승인 전
A36: 910035 | B36: 2 | C36: dk-terrain-contrast | D36: 3 | E36: 자료에 맞는 두 섬의 비교는? | F36: 서도는 가파르고 동도 상부는 비교적 완만하다 | G36: 동도는 서도보다 높고 더 뾰족하다 | H36: 두 섬은 같은 형태와 높이를 가진다 | I36: 1 | J36: 서도는 가파르게 솟은 모습이고, 동도는 정상 부근에 비교적 완만한 공간이 있어요. | K36: 서도는 가파르게 솟은 모습이고, 동도는 정상 부근에 비교적 완만한 공간이 있어요. | L36: 고른 보기 ‘동도는 서도보다 높고 더 뾰족하다’와 달라요. 이 문항의 정답은 ‘서도는 가파르고 동도 상부는 비교적 완만하다’입니다. 서도는 가파르게 솟은 모습이고, 동도는 정상 부근에 비교적 완만한 공간이 있어요. | M36: 고른 보기 ‘두 섬은 같은 형태와 높이를 가진다’와 달라요. 이 문항의 정답은 ‘서도는 가파르고 동도 상부는 비교적 완만하다’입니다. 서도는 가파르게 솟은 모습이고, 동도는 정상 부근에 비교적 완만한 공간이 있어요. | N36: 국가유산 설명과 항공사진을 함께 보면 서도의 가파른 형태와 동도의 비교적 평탄한 정상 부근을 구분할 수 있습니다. 동도도 해안 절벽과 능선이 있습니다. | O36: https://www.heritage.go.kr/heri/cul/culSelectDetail.do?VdkVgwKey=16%2C03360000%2C37&pageNo=1_1_2_0 https://www.jbe.go.kr/dokdo/assets/sub/picture.html | P36: =LEN(E36)+MAX(LEN(F36),LEN(G36),LEN(H36)) -> 40 | Q36: 출처 기반 자체 검토 / 독립 승인 전
A37: 910036 | B37: 2 | C37: dk-terrain-contrast | D37: 4 | E37: 동도를 완전히 평평한 판으로 그리면? | F37: 시설이 있으므로 평평한 판이 정확하다 | G37: 서도보다 낮으면 절벽도 없어야 한다 | H37: 상부의 상대적 특징을 섬 전체로 확대했다 | I37: 3 | J37: 서도는 가파르게 솟은 모습이고, 동도는 정상 부근에 비교적 완만한 공간이 있어요. | K37: 고른 보기 ‘시설이 있으므로 평평한 판이 정확하다’와 달라요. 이 문항의 정답은 ‘상부의 상대적 특징을 섬 전체로 확대했다’입니다. 서도는 가파르게 솟은 모습이고, 동도는 정상 부근에 비교적 완만한 공간이 있어요. | L37: 고른 보기 ‘서도보다 낮으면 절벽도 없어야 한다’와 달라요. 이 문항의 정답은 ‘상부의 상대적 특징을 섬 전체로 확대했다’입니다. 서도는 가파르게 솟은 모습이고, 동도는 정상 부근에 비교적 완만한 공간이 있어요. | M37: 서도는 가파르게 솟은 모습이고, 동도는 정상 부근에 비교적 완만한 공간이 있어요. | N37: 국가유산 설명과 항공사진을 함께 보면 서도의 가파른 형태와 동도의 비교적 평탄한 정상 부근을 구분할 수 있습니다. 동도도 해안 절벽과 능선이 있습니다. | O37: https://www.heritage.go.kr/heri/cul/culSelectDetail.do?VdkVgwKey=16%2C03360000%2C37&pageNo=1_1_2_0 https://www.jbe.go.kr/dokdo/assets/sub/picture.html | P37: =LEN(E37)+MAX(LEN(F37),LEN(G37),LEN(H37)) -> 42 | Q37: 출처 기반 자체 검토 / 독립 승인 전
A38: 910037 | B38: 2 | C38: dk-above-below | D38: 1 | E38: 독도의 지형은 바닷속에도 이어질까요? | F38: 배가 받치고 있어요 | G38: 네, 바닷속에도 이어져요 | H38: 아니요, 수면에 떠 있어요 | I38: 2 | J38: 독도는 큰 해저 화산체의 일부가 물 위에 드러난 모습이에요. 바닷속에도 지형이 이어져요. | K38: 고른 보기 ‘배가 받치고 있어요’와 달라요. 이 문항의 정답은 ‘네, 바닷속에도 이어져요’입니다. 독도는 큰 해저 화산체의 일부가 물 위에 드러난 모습이에요. 바닷속에도 지형이 이어져요. | L38: 독도는 큰 해저 화산체의 일부가 물 위에 드러난 모습이에요. 바닷속에도 지형이 이어져요. | M38: 고른 보기 ‘아니요, 수면에 떠 있어요’와 달라요. 이 문항의 정답은 ‘네, 바닷속에도 이어져요’입니다. 독도는 큰 해저 화산체의 일부가 물 위에 드러난 모습이에요. 바닷속에도 지형이 이어져요. | O38: https://www.dokdo.re.kr/home/cms/cmsCont.do?cntnts_sn=66 | P38: =LEN(E38)+MAX(LEN(F38),LEN(G38),LEN(H38)) -> 34 | Q38: 출처 기반 자체 검토 / 독립 승인 전
A39: 910038 | B39: 2 | C39: dk-above-below | D39: 2 | E39: 독도 화산체 전체를 보려면 어디도 살필까요? | F39: 바닷속 부분 | G39: 등대 지붕만 | H39: 동도 건물만 | I39: 1 | J39: 독도는 큰 해저 화산체의 일부가 물 위에 드러난 모습이에요. 바닷속에도 지형이 이어져요. | K39: 독도는 큰 해저 화산체의 일부가 물 위에 드러난 모습이에요. 바닷속에도 지형이 이어져요. | L39: 고른 보기 ‘등대 지붕만’와 달라요. 이 문항의 정답은 ‘바닷속 부분’입니다. 독도는 큰 해저 화산체의 일부가 물 위에 드러난 모습이에요. 바닷속에도 지형이 이어져요. | M39: 고른 보기 ‘동도 건물만’와 달라요. 이 문항의 정답은 ‘바닷속 부분’입니다. 독도는 큰 해저 화산체의 일부가 물 위에 드러난 모습이에요. 바닷속에도 지형이 이어져요. | O39: https://www.dokdo.re.kr/home/cms/cmsCont.do?cntnts_sn=66 | P39: =LEN(E39)+MAX(LEN(F39),LEN(G39),LEN(H39)) -> 30 | Q39: 출처 기반 자체 검토 / 독립 승인 전
A40: 910039 | B40: 2 | C40: dk-above-below | D40: 3 | E40: 168.5m와 약 2,300m가 함께 쓰이는 이유는? | F40: 서도의 높이가 하루마다 크게 달라진다 | G40: 두 수치는 모두 땅의 넓이이다 | H40: 수면과 해저 기저부라는 기준이 다르다 | I40: 3 | J40: 독도는 큰 해저 화산체의 일부가 물 위에 드러난 모습이에요. 바닷속에도 지형이 이어져요. | K40: 고른 보기 ‘서도의 높이가 하루마다 크게 달라진다’와 달라요. 이 문항의 정답은 ‘수면과 해저 기저부라는 기준이 다르다’입니다. 독도는 큰 해저 화산체의 일부가 물 위에 드러난 모습이에요. 바닷속에도 지형이 이어져요. | L40: 고른 보기 ‘두 수치는 모두 땅의 넓이이다’와 달라요. 이 문항의 정답은 ‘수면과 해저 기저부라는 기준이 다르다’입니다. 독도는 큰 해저 화산체의 일부가 물 위에 드러난 모습이에요. 바닷속에도 지형이 이어져요. | M40: 독도는 큰 해저 화산체의 일부가 물 위에 드러난 모습이에요. 바닷속에도 지형이 이어져요. | N40: 수면 위 최고 높이: 서도 168.5m·동도 98.6m. 해저 기저부부터 본 독도 화산체 전체 높이: 약 2,300m. 높이의 기준점이 다릅니다. | O40: https://www.dokdo.re.kr/home/cms/cmsCont.do?cntnts_sn=66 | P40: =LEN(E40)+MAX(LEN(F40),LEN(G40),LEN(H40)) -> 49 | Q40: 출처 기반 자체 검토 / 독립 승인 전
...

Sheet 문항_EN
A1: 문항 ID | B1: 단원 | C1: 개념 묶음 | D1: 인지단계 | E1: 질문 | F1: 보기 1 | G1: 보기 2 | H1: 보기 3 | I1: 정답 번호 | J1: 사실·해설 | K1: 오답 해설 1 | L1: 오답 해설 2 | M1: 오답 해설 3 | N1: 판단 자료 | O1: 출처 URL | P1: 질문+최장보기 글자수 | Q1: 검토 상태
A2: 910001 | B2: 1 | C2: dk-composition | D2: 1 | E2: Which are Dokdo’s two main islands? | F2: Jejudo and Seodo | G2: Dongdo and Seodo | H2: Ulleungdo and Dongdo | I2: 2 | J2: Dokdo consists of Dongdo, Seodo and smaller surrounding rocky islets. | K2: The selected option, “Jejudo and Seodo”, does not fit. The answer is “Dongdo and Seodo”. Dokdo consists of Dongdo, Seodo and smaller surrounding rocky islets. | L2: Dokdo consists of Dongdo, Seodo and smaller surrounding rocky islets. | M2: The selected option, “Ulleungdo and Dongdo”, does not fit. The answer is “Dongdo and Seodo”. Dokdo consists of Dongdo, Seodo and smaller surrounding rocky islets. | O2: https://dokdo.mofa.go.kr/kor/introduce/location.jsp | P2: =LEN(E2)+MAX(LEN(F2),LEN(G2),LEN(H2)) -> 55 | Q2: 출처 기반 자체 검토 / 독립 승인 전
A3: 910002 | B3: 1 | C3: dk-composition | D3: 2 | E3: What is missing if only the two main islands are drawn? | F3: The surrounding smaller islets | G3: The locations of the two main islands | H3: Seodo itself | I3: 1 | J3: Dokdo consists of Dongdo, Seodo and smaller surrounding rocky islets. | K3: Dokdo consists of Dongdo, Seodo and smaller surrounding rocky islets. | L3: The selected option, “The locations of the two main islands”, does not fit. The answer is “The surrounding smaller islets”. Dokdo consists of Dongdo, Seodo and smaller surrounding rocky islets. | M3: The selected option, “Seodo itself”, does not fit. The answer is “The surrounding smaller islets”. Dokdo consists of Dongdo, Seodo and smaller surrounding rocky islets. | O3: https://dokdo.mofa.go.kr/kor/introduce/location.jsp | P3: =LEN(E3)+MAX(LEN(F3),LEN(G3),LEN(H3)) -> 92 | Q3: 출처 기반 자체 검토 / 독립 승인 전
A4: 910003 | B4: 1 | C4: dk-composition | D4: 3 | E4: What does the number 89 count in the source? | F4: All islands including Dongdo and Seodo | G4: Peaks within Dongdo | H4: Associated islets counted separately from the two main islands | I4: 3 | J4: Dokdo consists of Dongdo, Seodo and smaller surrounding rocky islets. | K4: The selected option, “All islands including Dongdo and Seodo”, does not fit. The answer is “Associated islets counted separately from the two main islands”. Dokdo consists of Dongdo, Seodo and smaller surrounding rocky islets. | L4: The selected option, “Peaks within Dongdo”, does not fit. The answer is “Associated islets counted separately from the two main islands”. Dokdo consists of Dongdo, Seodo and smaller surrounding rocky islets. | M4: Dokdo consists of Dongdo, Seodo and smaller surrounding rocky islets. | N4: MOFA describes Dokdo as the two main islands Dongdo and Seodo, plus 89 associated islets. | O4: https://dokdo.mofa.go.kr/kor/introduce/location.jsp | P4: =LEN(E4)+MAX(LEN(F4),LEN(G4),LEN(H4)) -> 106 | Q4: 출처 기반 자체 검토 / 독립 승인 전
A5: 910004 | B5: 1 | C5: dk-composition | D5: 4 | E5: How should “Dokdo consists of only two islands” be revised? | F5: Describe all 89 as main islands | G5: Distinguish the main islands from associated islets | H5: Exclude all smaller islets from Dokdo | I5: 2 | J5: Dokdo consists of Dongdo, Seodo and smaller surrounding rocky islets. Naming the principal islands is not a complete description of the group. | K5: The selected option, “Describe all 89 as main islands”, does not fit. The answer is “Distinguish the main islands from associated islets”. Dokdo consists of Dongdo, Seodo and smaller surrounding rocky islets. Naming the principal islands is not a complete description of the group. | L5: Dokdo consists of Dongdo, Seodo and smaller surrounding rocky islets. Naming the principal islands is not a complete description of the group. | M5: The selected option, “Exclude all smaller islets from Dokdo”, does not fit. The answer is “Distinguish the main islands from associated islets”. Dokdo consists of Dongdo, Seodo and smaller surrounding rocky islets. Naming the principal islands is not a complete description of the group. | N5: MOFA describes Dokdo as the two main islands Dongdo and Seodo, plus 89 associated islets. | O5: https://dokdo.mofa.go.kr/kor/introduce/location.jsp | P5: =LEN(E5)+MAX(LEN(F5),LEN(G5),LEN(H5)) -> 110 | Q5: 출처 기반 자체 검토 / 독립 승인 전
A6: 910005 | B6: 1 | C6: dk-relative-location | D6: 1 | E6: In which direction is Dokdo from Ulleungdo? | F6: Southeast | G6: Northwest | H6: Southwest | I6: 1 | J6: Dokdo lies about 87.4 km southeast of Ulleungdo. | K6: Dokdo lies about 87.4 km southeast of Ulleungdo. | L6: The selected option, “Northwest”, does not fit. The answer is “Southeast”. Dokdo lies about 87.4 km southeast of Ulleungdo. | M6: The selected option, “Southwest”, does not fit. The answer is “Southeast”. Dokdo lies about 87.4 km southeast of Ulleungdo. | O6: https://dokdo.mofa.go.kr/kor/introduce/location.jsp | P6: =LEN(E6)+MAX(LEN(F6),LEN(G6),LEN(H6)) -> 52 | Q6: 출처 기반 자체 검토 / 독립 승인 전
A7: 910006 | B7: 1 | C7: dk-relative-location | D7: 2 | E7: How are Ulleungdo and Dokdo related geographically? | F7: Names for two sides of one island | G7: Both are within Dongdo | H7: Separate islands with sea between them | I7: 3 | J7: Dokdo lies about 87.4 km southeast of Ulleungdo. | K7: The selected option, “Names for two sides of one island”, does not fit. The answer is “Separate islands with sea between them”. Dokdo lies about 87.4 km southeast of Ulleungdo. | L7: The selected option, “Both are within Dongdo”, does not fit. The answer is “Separate islands with sea between them”. Dokdo lies about 87.4 km southeast of Ulleungdo. | M7: Dokdo lies about 87.4 km southeast of Ulleungdo. | O7: https://dokdo.mofa.go.kr/kor/introduce/location.jsp | P7: =LEN(E7)+MAX(LEN(F7),LEN(G7),LEN(H7)) -> 89 | Q7: 출처 기반 자체 검토 / 독립 승인 전
A8: 910007 | B8: 1 | C8: dk-relative-location | D8: 3 | E8: Which place is closer to Dokdo in the supplied data? | F8: Both are equally far away | G8: Ulleungdo | H8: The Oki Islands | I8: 2 | J8: Dokdo lies about 87.4 km southeast of Ulleungdo. 87.4 km is shorter than 157.5 km. | K8: The selected option, “Both are equally far away”, does not fit. The answer is “Ulleungdo”. Dokdo lies about 87.4 km southeast of Ulleungdo. 87.4 km is shorter than 157.5 km. | L8: Dokdo lies about 87.4 km southeast of Ulleungdo. 87.4 km is shorter than 157.5 km. | M8: The selected option, “The Oki Islands”, does not fit. The answer is “Ulleungdo”. Dokdo lies about 87.4 km southeast of Ulleungdo. 87.4 km is shorter than 157.5 km. | N8: Distances from Dokdo: Ulleungdo 87.4 km; Japan’s Oki Islands 157.5 km. Both measurements start at Dokdo. | O8: https://dokdo.mofa.go.kr/kor/introduce/location.jsp | P8: =LEN(E8)+MAX(LEN(F8),LEN(G8),LEN(H8)) -> 77 | Q8: 출처 기반 자체 검토 / 독립 승인 전
A9: 910008 | B9: 1 | C9: dk-relative-location | D9: 4 | E9: Which claim is supported by this distance table alone? | F9: Ulleungdo is closer to Dokdo than Oki is | G9: Distance alone determines all territorial history | H9: Ulleungdo and Dokdo are connected by land | I9: 1 | J9: Dokdo lies about 87.4 km southeast of Ulleungdo. A distance comparison is distinct from assessing historical and legal evidence. | K9: Dokdo lies about 87.4 km southeast of Ulleungdo. A distance comparison is distinct from assessing historical and legal evidence. | L9: The selected option, “Distance alone determines all territorial history”, does not fit. The answer is “Ulleungdo is closer to Dokdo than Oki is”. Dokdo lies about 87.4 km southeast of Ulleungdo. A distance comparison is distinct from assessing historical and legal evidence. | M9: The selected option, “Ulleungdo and Dokdo are connected by land”, does not fit. The answer is “Ulleungdo is closer to Dokdo than Oki is”. Dokdo lies about 87.4 km southeast of Ulleungdo. A distance comparison is distinct from assessing historical and legal evidence. | N9: Distances from Dokdo: Ulleungdo 87.4 km; Japan’s Oki Islands 157.5 km. Both measurements start at Dokdo. | O9: https://dokdo.mofa.go.kr/kor/introduce/location.jsp | P9: =LEN(E9)+MAX(LEN(F9),LEN(G9),LEN(H9)) -> 103 | Q9: 출처 기반 자체 검토 / 독립 승인 전
A10: 910009 | B10: 1 | C10: dk-orientation | D10: 1 | E10: What is Dokdo’s eastern main island called? | F10: Seodo | G10: Ulleungdo | H10: Dongdo | I10: 3 | J10: Seodo is the western main island and Dongdo the eastern one. Rotating a map does not change geographic directions. | K10: The selected option, “Seodo”, does not fit. The answer is “Dongdo”. Seodo is the western main island and Dongdo the eastern one. Rotating a map does not change geographic directions. | L10: The selected option, “Ulleungdo”, does not fit. The answer is “Dongdo”. Seodo is the western main island and Dongdo the eastern one. Rotating a map does not change geographic directions. | M10: Seodo is the western main island and Dongdo the eastern one. Rotating a map does not change geographic directions. | O10: https://dokdo.mofa.go.kr/kor/introduce/location.jsp | P10: =LEN(E10)+MAX(LEN(F10),LEN(G10),LEN(H10)) -> 52 | Q10: 출처 기반 자체 검토 / 독립 승인 전
A11: 910010 | B11: 1 | C11: dk-orientation | D11: 2 | E11: Which direction is linked to “seo” in Seodo? | F11: North | G11: West | H11: East | I11: 2 | J11: Seodo is the western main island and Dongdo the eastern one. Rotating a map does not change geographic directions. | K11: The selected option, “North”, does not fit. The answer is “West”. Seodo is the western main island and Dongdo the eastern one. Rotating a map does not change geographic directions. | L11: Seodo is the western main island and Dongdo the eastern one. Rotating a map does not change geographic directions. | M11: The selected option, “East”, does not fit. The answer is “West”. Seodo is the western main island and Dongdo the eastern one. Rotating a map does not change geographic directions. | O11: https://dokdo.mofa.go.kr/kor/introduce/location.jsp | P11: =LEN(E11)+MAX(LEN(F11),LEN(G11),LEN(H11)) -> 49 | Q11: 출처 기반 자체 검토 / 독립 승인 전
A12: 910011 | B12: 1 | C12: dk-orientation | D12: 3 | E12: On the supplied schematic, where is Dongdo relative to Seodo? | F12: To the right | G12: To the left | H12: At the same point | I12: 1 | J12: Seodo is the western main island and Dongdo the eastern one. Rotating a map does not change geographic directions. | K12: Seodo is the western main island and Dongdo the eastern one. Rotating a map does not change geographic directions. | L12: The selected option, “To the left”, does not fit. The answer is “To the right”. Seodo is the western main island and Dongdo the eastern one. Rotating a map does not change geographic directions. | M12: The selected option, “At the same point”, does not fit. The answer is “To the right”. Seodo is the western main island and Dongdo the eastern one. Rotating a map does not change geographic directions. | N12: Orientation diagram: north up, west left, east right. Seodo is on the left and Dongdo on the right. This schematic does not measure shorelines or distance. | O12: https://dokdo.mofa.go.kr/kor/introduce/location.jsp | P12: =LEN(E12)+MAX(LEN(F12),LEN(G12),LEN(H12)) -> 78 | Q12: 출처 기반 자체 검토 / 독립 승인 전
A13: 910012 | B13: 1 | C13: dk-orientation | D13: 4 | E13: What if a rotated map shows Dongdo on the left? | F13: Rename Dongdo as Seodo | G13: Conclude that the island physically moved | H13: Use the compass marker to determine east and west | I13: 3 | J13: Seodo is the western main island and Dongdo the eastern one. Rotating a map does not change geographic directions. Screen left and right need not correspond to geographic west and east. | K13: The selected option, “Rename Dongdo as Seodo”, does not fit. The answer is “Use the compass marker to determine east and west”. Seodo is the western main island and Dongdo the eastern one. Rotating a map does not change geographic directions. Screen left and right need not correspond to geographic west and east. | L13: The selected option, “Conclude that the island physically moved”, does not fit. The answer is “Use the compass marker to determine east and west”. Seodo is the western main island and Dongdo the eastern one. Rotating a map does not change geographic directions. Screen left and right need not correspond to geographic west and east. | M13: Seodo is the western main island and Dongdo the eastern one. Rotating a map does not change geographic directions. Screen left and right need not correspond to geographic west and east. | N13: Orientation diagram: north up, west left, east right. Seodo is on the left and Dongdo on the right. This schematic does not measure shorelines or distance. | O13: https://dokdo.mofa.go.kr/kor/introduce/location.jsp | P13: =LEN(E13)+MAX(LEN(F13),LEN(G13),LEN(H13)) -> 96 | Q13: 출처 기반 자체 검토 / 독립 승인 전
A14: 910013 | B14: 1 | C14: dk-visibility | D14: 1 | E14: What weather helps people see Dokdo from Ulleungdo? | F14: Rain obscuring the view | G14: A clear day | H14: Thick fog | I14: 2 | J14: Dokdo can be seen from Ulleungdo in clear weather. Fog or rain can obscure the view. | K14: The selected option, “Rain obscuring the view”, does not fit. The answer is “A clear day”. Dokdo can be seen from Ulleungdo in clear weather. Fog or rain can obscure the view. | L14: Dokdo can be seen from Ulleungdo in clear weather. Fog or rain can obscure the view. | M14: The selected option, “Thick fog”, does not fit. The answer is “A clear day”. Dokdo can be seen from Ulleungdo in clear weather. Fog or rain can obscure the view. | O14: https://dokdo.mofa.go.kr/kor/introduce/location.jsp https://dokdo.mofa.go.kr/kor/pds/part06_view02.jsp | P14: =LEN(E14)+MAX(LEN(F14),LEN(G14),LEN(H14)) -> 74 | Q14: 출처 기반 자체 검토 / 독립 승인 전
A15: 910014 | B15: 1 | C15: dk-visibility | D15: 2 | E15: What should be considered if Dokdo is not visible today? | F15: Weather conditions such as fog | G15: A change of island name | H15: An increase in Seodo’s area | I15: 1 | J15: Dokdo can be seen from Ulleungdo in clear weather. Fog or rain can obscure the view. | K15: Dokdo can be seen from Ulleungdo in clear weather. Fog or rain can obscure the view. | L15: The selected option, “A change of island name”, does not fit. The answer is “Weather conditions such as fog”. Dokdo can be seen from Ulleungdo in clear weather. Fog or rain can obscure the view. | M15: The selected option, “An increase in Seodo’s area”, does not fit. The answer is “Weather conditions such as fog”. Dokdo can be seen from Ulleungdo in clear weather. Fog or rain can obscure the view. | O15: https://dokdo.mofa.go.kr/kor/introduce/location.jsp https://dokdo.mofa.go.kr/kor/pds/part06_view02.jsp | P15: =LEN(E15)+MAX(LEN(F15),LEN(G15),LEN(H15)) -> 86 | Q15: 출처 기반 자체 검토 / 독립 승인 전
A16: 910015 | B16: 1 | C16: dk-visibility | D16: 3 | E16: What condition does the old passage place on visibility? | F16: Always, in all weather | G16: Only in winter | H16: When the weather is clear | I16: 3 | J16: Dokdo can be seen from Ulleungdo in clear weather. Fog or rain can obscure the view. | K16: The selected option, “Always, in all weather”, does not fit. The answer is “When the weather is clear”. Dokdo can be seen from Ulleungdo in clear weather. Fog or rain can obscure the view. | L16: The selected option, “Only in winter”, does not fit. The answer is “When the weather is clear”. Dokdo can be seen from Ulleungdo in clear weather. Fog or rain can obscure the view. | M16: Dokdo can be seen from Ulleungdo in clear weather. Fog or rain can obscure the view. | N16: The MOFA presentation of the geographical appendix to the Annals of Sejong says the islands Usan and Mureung can be seen in clear weather. | O16: https://dokdo.mofa.go.kr/kor/introduce/location.jsp https://dokdo.mofa.go.kr/kor/pds/part06_view02.jsp | P16: =LEN(E16)+MAX(LEN(F16),LEN(G16),LEN(H16)) -> 81 | Q16: 출처 기반 자체 검토 / 독립 승인 전
A17: 910016 | B17: 1 | C17: dk-visibility | D17: 4 | E17: Is “Dokdo is always visible from Ulleungdo” accurate? | F17: Weather never affects the visibility of nearby islands | G17: No; it omits the clear-weather condition | H17: Yes; the correct island names are sufficient | I17: 2 | J17: Dokdo can be seen from Ulleungdo in clear weather. Fog or rain can obscure the view. | K17: The selected option, “Weather never affects the visibility of nearby islands”, does not fit. The answer is “No; it omits the clear-weather condition”. Dokdo can be seen from Ulleungdo in clear weather. Fog or rain can obscure the view. | L17: Dokdo can be seen from Ulleungdo in clear weather. Fog or rain can obscure the view. | M17: The selected option, “Yes; the correct island names are sufficient”, does not fit. The answer is “No; it omits the clear-weather condition”. Dokdo can be seen from Ulleungdo in clear weather. Fog or rain can obscure the view. | N17: The MOFA presentation of the geographical appendix to the Annals of Sejong says the islands Usan and Mureung can be seen in clear weather. | O17: https://dokdo.mofa.go.kr/kor/introduce/location.jsp https://dokdo.mofa.go.kr/kor/pds/part06_view02.jsp | P17: =LEN(E17)+MAX(LEN(F17),LEN(G17),LEN(H17)) -> 107 | Q17: 출처 기반 자체 검토 / 독립 승인 전
A18: 910017 | B18: 1 | C18: dk-islet-count | D18: 1 | E18: Are the smaller rocky islets part of Dokdo? | F18: Yes, they are part of Dokdo | G18: No, only the main islands are Dokdo | H18: They all belong to Ulleungdo | I18: 1 | J18: Dokdo’s total land area includes the associated islets as well as Dongdo and Seodo. | K18: Dokdo’s total land area includes the associated islets as well as Dongdo and Seodo. | L18: The selected option, “No, only the main islands are Dokdo”, does not fit. The answer is “Yes, they are part of Dokdo”. Dokdo’s total land area includes the associated islets as well as Dongdo and Seodo. | M18: The selected option, “They all belong to Ulleungdo”, does not fit. The answer is “Yes, they are part of Dokdo”. Dokdo’s total land area includes the associated islets as well as Dongdo and Seodo. | O18: https://dokdo.mofa.go.kr/kor/introduce/location.jsp | P18: =LEN(E18)+MAX(LEN(F18),LEN(G18),LEN(H18)) -> 78 | Q18: 출처 기반 자체 검토 / 독립 승인 전
A19: 910018 | B19: 1 | C19: dk-islet-count | D19: 2 | E19: What must be included in Dokdo’s total land area? | F19: The elevations of the main islands | G19: The whole area of Ulleungdo | H19: The main islands and associated islets | I19: 3 | J19: Dokdo’s total land area includes the associated islets as well as Dongdo and Seodo. | K19: The selected option, “The elevations of the main islands”, does not fit. The answer is “The main islands and associated islets”. Dokdo’s total land area includes the associated islets as well as Dongdo and Seodo. | L19: The selected option, “The whole area of Ulleungdo”, does not fit. The answer is “The main islands and associated islets”. Dokdo’s total land area includes the associated islets as well as Dongdo and Seodo. | M19: Dokdo’s total land area includes the associated islets as well as Dongdo and Seodo. | O19: https://dokdo.mofa.go.kr/kor/introduce/location.jsp | P19: =LEN(E19)+MAX(LEN(F19),LEN(G19),LEN(H19)) -> 87 | Q19: 출처 기반 자체 검토 / 독립 승인 전
A20: 910019 | B20: 1 | C20: dk-islet-count | D20: 3 | E20: Why is the sum of the two main island areas below the total? | F20: Elevations were omitted from the area calculation | G20: Associated islets add land area | H20: The sea was counted twice | I20: 2 | J20: Dokdo’s total land area includes the associated islets as well as Dongdo and Seodo. | K20: The selected option, “Elevations were omitted from the area calculation”, does not fit. The answer is “Associated islets add land area”. Dokdo’s total land area includes the associated islets as well as Dongdo and Seodo. | L20: Dokdo’s total land area includes the associated islets as well as Dongdo and Seodo. | M20: The selected option, “The sea was counted twice”, does not fit. The answer is “Associated islets add land area”. Dokdo’s total land area includes the associated islets as well as Dongdo and Seodo. | N20: Areas: Dongdo 73,297 m²; Seodo 88,740 m²; Dokdo total 187,554 m². The total includes associated islets. | O20: https://dokdo.mofa.go.kr/kor/introduce/location.jsp | P20: =LEN(E20)+MAX(LEN(F20),LEN(G20),LEN(H20)) -> 109 | Q20: 출처 기반 자체 검토 / 독립 승인 전
A21: 910020 | B21: 1 | C21: dk-islet-count | D21: 4 | E21: What is wrong with using one photo’s rock count as the total? | F21: It may miss islets outside the frame | G21: None of the photographed rocks is part of Dokdo | H21: A photograph necessarily shows the whole group | I21: 1 | J21: Dokdo’s total land area includes the associated islets as well as Dongdo and Seodo. | K21: Dokdo’s total land area includes the associated islets as well as Dongdo and Seodo. | L21: The selected option, “None of the photographed rocks is part of Dokdo”, does not fit. The answer is “It may miss islets outside the frame”. Dokdo’s total land area includes the associated islets as well as Dongdo and Seodo. | M21: The selected option, “A photograph necessarily shows the whole group”, does not fit. The answer is “It may miss islets outside the frame”. Dokdo’s total land area includes the associated islets as well as Dongdo and Seodo. | N21: Areas: Dongdo 73,297 m²; Seodo 88,740 m²; Dokdo total 187,554 m². The total includes associated islets. | O21: https://dokdo.mofa.go.kr/kor/introduce/location.jsp | P21: =LEN(E21)+MAX(LEN(F21),LEN(G21),LEN(H21)) -> 108 | Q21: 출처 기반 자체 검토 / 독립 승인 전
A22: 910021 | B22: 2 | C22: dk-heights | D22: 1 | E22: Which main island is higher? | F22: Dongdo | G22: They are equally high | H22: Seodo | I22: 3 | J22: Seodo’s maximum elevation is 168.5 m; Dongdo’s is 98.6 m. Seodo is higher. | K22: The selected option, “Dongdo”, does not fit. The answer is “Seodo”. Seodo’s maximum elevation is 168.5 m; Dongdo’s is 98.6 m. Seodo is higher. | L22: The selected option, “They are equally high”, does not fit. The answer is “Seodo”. Seodo’s maximum elevation is 168.5 m; Dongdo’s is 98.6 m. Seodo is higher. | M22: Seodo’s maximum elevation is 168.5 m; Dongdo’s is 98.6 m. Seodo is higher. | O22: https://dokdo.mofa.go.kr/kor/introduce/location.jsp | P22: =LEN(E22)+MAX(LEN(F22),LEN(G22),LEN(H22)) -> 49 | Q22: 출처 기반 자체 검토 / 독립 승인 전
A23: 910022 | B23: 2 | C23: dk-heights | D23: 2 | E23: Which elevation pairing is correct? | F23: Both 168.5 m | G23: Seodo 168.5 m; Dongdo 98.6 m | H23: Seodo 98.6 m; Dongdo 168.5 m | I23: 2 | J23: Seodo’s maximum elevation is 168.5 m; Dongdo’s is 98.6 m. Seodo is higher. | K23: The selected option, “Both 168.5 m”, does not fit. The answer is “Seodo 168.5 m; Dongdo 98.6 m”. Seodo’s maximum elevation is 168.5 m; Dongdo’s is 98.6 m. Seodo is higher. | L23: Seodo’s maximum elevation is 168.5 m; Dongdo’s is 98.6 m. Seodo is higher. | M23: The selected option, “Seodo 98.6 m; Dongdo 168.5 m”, does not fit. The answer is “Seodo 168.5 m; Dongdo 98.6 m”. Seodo’s maximum elevation is 168.5 m; Dongdo’s is 98.6 m. Seodo is higher. | O23: https://dokdo.mofa.go.kr/kor/introduce/location.jsp | P23: =LEN(E23)+MAX(LEN(F23),LEN(G23),LEN(H23)) -> 63 | Q23: 출처 기반 자체 검토 / 독립 승인 전
A24: 910023 | B24: 2 | C24: dk-heights | D24: 3 | E24: What is the difference in the listed maximum elevations? | F24: 69.9 m | G24: 267.1 m | H24: 87.4 m | I24: 1 | J24: Seodo’s maximum elevation is 168.5 m; Dongdo’s is 98.6 m. Seodo is higher. 168.5 minus 98.6 is 69.9 m. This asks for a difference, not a sum. | K24: Seodo’s maximum elevation is 168.5 m; Dongdo’s is 98.6 m. Seodo is higher. 168.5 minus 98.6 is 69.9 m. This asks for a difference, not a sum. | L24: The selected option, “267.1 m”, does not fit. The answer is “69.9 m”. Seodo’s maximum elevation is 168.5 m; Dongdo’s is 98.6 m. Seodo is higher. 168.5 minus 98.6 is 69.9 m. This asks for a difference, not a sum. | M24: The selected option, “87.4 m”, does not fit. The answer is “69.9 m”. Seodo’s maximum elevation is 168.5 m; Dongdo’s is 98.6 m. Seodo is higher. 168.5 minus 98.6 is 69.9 m. This asks for a difference, not a sum. | N24: Elevations above sea level: Seodo 168.5 m; Dongdo 98.6 m. | O24: https://dokdo.mofa.go.kr/kor/introduce/location.jsp | P24: =LEN(E24)+MAX(LEN(F24),LEN(G24),LEN(H24)) -> 63 | Q24: 출처 기반 자체 검토 / 독립 승인 전
A25: 910024 | B25: 2 | C25: dk-heights | D25: 4 | E25: What if Dongdo looks larger in a photograph? | F25: Use image size alone to call Dongdo higher | G25: Assume actual elevation changes with each photo | H25: Consider perspective and measured elevation | I25: 3 | J25: Seodo’s maximum elevation is 168.5 m; Dongdo’s is 98.6 m. Seodo is higher. | K25: The selected option, “Use image size alone to call Dongdo higher”, does not fit. The answer is “Consider perspective and measured elevation”. Seodo’s maximum elevation is 168.5 m; Dongdo’s is 98.6 m. Seodo is higher. | L25: The selected option, “Assume actual elevation changes with each photo”, does not fit. The answer is “Consider perspective and measured elevation”. Seodo’s maximum elevation is 168.5 m; Dongdo’s is 98.6 m. Seodo is higher. | M25: Seodo’s maximum elevation is 168.5 m; Dongdo’s is 98.6 m. Seodo is higher. | N25: Elevations above sea level: Seodo 168.5 m; Dongdo 98.6 m. | O25: https://dokdo.mofa.go.kr/kor/introduce/location.jsp | P25: =LEN(E25)+MAX(LEN(F25),LEN(G25),LEN(H25)) -> 91 | Q25: 출처 기반 자체 검토 / 독립 승인 전
A26: 910025 | B26: 2 | C26: dk-area | D26: 1 | E26: Which main island has the larger land area? | F26: They have equal land areas | G26: Seodo | H26: Dongdo | I26: 2 | J26: Seodo has a larger land area than Dongdo. Elevation and area are different measurements. | K26: The selected option, “They have equal land areas”, does not fit. The answer is “Seodo”. Seodo has a larger land area than Dongdo. Elevation and area are different measurements. | L26: Seodo has a larger land area than Dongdo. Elevation and area are different measurements. | M26: The selected option, “Dongdo”, does not fit. The answer is “Seodo”. Seodo has a larger land area than Dongdo. Elevation and area are different measurements. | O26: https://dokdo.mofa.go.kr/kor/introduce/location.jsp | P26: =LEN(E26)+MAX(LEN(F26),LEN(G26),LEN(H26)) -> 69 | Q26: 출처 기반 자체 검토 / 독립 승인 전
A27: 910026 | B27: 2 | C27: dk-area | D27: 2 | E27: What does “Seodo has a larger area” compare? | F27: The extent of land | G27: Sea depth | H27: Lighthouse height | I27: 1 | J27: Seodo has a larger land area than Dongdo. Elevation and area are different measurements. | K27: Seodo has a larger land area than Dongdo. Elevation and area are different measurements. | L27: The selected option, “Sea depth”, does not fit. The answer is “The extent of land”. Seodo has a larger land area than Dongdo. Elevation and area are different measurements. | M27: The selected option, “Lighthouse height”, does not fit. The answer is “The extent of land”. Seodo has a larger land area than Dongdo. Elevation and area are different measurements. | O27: https://dokdo.mofa.go.kr/kor/introduce/location.jsp | P27: =LEN(E27)+MAX(LEN(F27),LEN(G27),LEN(H27)) -> 62 | Q27: 출처 기반 자체 검토 / 독립 승인 전
A28: 910027 | B28: 2 | C28: dk-area | D28: 3 | E28: Which values should be used to compare land area? | F28: 168.5 m and 98.6 m | G28: 87.4 km and 151 m | H28: 88,740 m² and 73,297 m² | I28: 3 | J28: Seodo has a larger land area than Dongdo. Elevation and area are different measurements. | K28: The selected option, “168.5 m and 98.6 m”, does not fit. The answer is “88,740 m² and 73,297 m²”. Seodo has a larger land area than Dongdo. Elevation and area are different measurements. | L28: The selected option, “87.4 km and 151 m”, does not fit. The answer is “88,740 m² and 73,297 m²”. Seodo has a larger land area than Dongdo. Elevation and area are different measurements. | M28: Seodo has a larger land area than Dongdo. Elevation and area are different measurements. | N28: Seodo area: 88,740 m²; Dongdo area: 73,297 m². Elevation uses metres; area uses square metres. | O28: https://dokdo.mofa.go.kr/kor/introduce/location.jsp | P28: =LEN(E28)+MAX(LEN(F28),LEN(G28),LEN(H28)) -> 72 | Q28: 출처 기반 자체 검토 / 독립 승인 전
A29: 910028 | B29: 2 | C29: dk-area | D29: 4 | E29: Evaluate “Seodo is higher, so it must have a larger area.” | F29: A higher island always has a smaller area | G29: Area must be checked with separate area data | H29: Correct, because adding heights produces area | I29: 2 | J29: Seodo has a larger land area than Dongdo. Elevation and area are different measurements. Both are greater for Seodo in this case, but elevation alone does not establish area. | K29: The selected option, “A higher island always has a smaller area”, does not fit. The answer is “Area must be checked with separate area data”. Seodo has a larger land area than Dongdo. Elevation and area are different measurements. Both are greater for Seodo in this case, but elevation alone does not establish area. | L29: Seodo has a larger land area than Dongdo. Elevation and area are different measurements. Both are greater for Seodo in this case, but elevation alone does not establish area. | M29: The selected option, “Correct, because adding heights produces area”, does not fit. The answer is “Area must be checked with separate area data”. Seodo has a larger land area than Dongdo. Elevation and area are different measurements. Both are greater for Seodo in this case, but elevation alone does not establish area. | N29: Seodo area: 88,740 m²; Dongdo area: 73,297 m². Elevation uses metres; area uses square metres. | O29: https://dokdo.mofa.go.kr/kor/introduce/location.jsp | P29: =LEN(E29)+MAX(LEN(F29),LEN(G29),LEN(H29)) -> 103 | Q29: 출처 기반 자체 검토 / 독립 승인 전
A30: 910029 | B30: 2 | C30: dk-shore-gap | D30: 1 | E30: What fills the gap between Dongdo and Seodo? | F30: Seawater | G30: An above-water land bridge | H30: A mountain on Ulleungdo | I30: 1 | J30: Dongdo and Seodo are separated by water, with about 151 m between their nearest shores. | K30: Dongdo and Seodo are separated by water, with about 151 m between their nearest shores. | L30: The selected option, “An above-water land bridge”, does not fit. The answer is “Seawater”. Dongdo and Seodo are separated by water, with about 151 m between their nearest shores. | M30: The selected option, “A mountain on Ulleungdo”, does not fit. The answer is “Seawater”. Dongdo and Seodo are separated by water, with about 151 m between their nearest shores. | O30: https://www.dokdo.re.kr/home/cms/cmsCont.do?cntnts_sn=66 | P30: =LEN(E30)+MAX(LEN(F30),LEN(G30),LEN(H30)) -> 70 | Q30: 출처 기반 자체 검토 / 독립 승인 전
A31: 910030 | B31: 2 | C31: dk-shore-gap | D31: 2 | E31: Which measurement is linked to 151 m? | F31: Seodo’s maximum elevation | G31: The distance from Ulleungdo to Dokdo | H31: The shortest shore-to-shore distance | I31: 3 | J31: Dongdo and Seodo are separated by water, with about 151 m between their nearest shores. | K31: The selected option, “Seodo’s maximum elevation”, does not fit. The answer is “The shortest shore-to-shore distance”. Dongdo and Seodo are separated by water, with about 151 m between their nearest shores. | L31: The selected option, “The distance from Ulleungdo to Dokdo”, does not fit. The answer is “The shortest shore-to-shore distance”. Dongdo and Seodo are separated by water, with about 151 m between their nearest shores. | M31: Dongdo and Seodo are separated by water, with about 151 m between their nearest shores. | O31: https://www.dokdo.re.kr/home/cms/cmsCont.do?cntnts_sn=66 | P31: =LEN(E31)+MAX(LEN(F31),LEN(G31),LEN(H31)) -> 73 | Q31: 출처 기반 자체 검토 / 독립 승인 전
