Workbook

Sheet 요약
A1: 독도 코리아 스쿨 · 질문 전수 수정 1.2
A2: 실제 출제 240문항의 한국어·영어 쌍 / 원래 1,513문항은 미재작성 보관 / 독립 교육 검수 전
A5: 수정 문항 쌍 | B5: =COUNTA('문항240'!A2:A241) -> 240
A6: 보기별 해설 쌍 | B6: =COUNTA('보기해설711'!A2:A712) -> 711
A7: 자료가 필요한 문항 | B7: =COUNTIF('자료와출처'!C2:C241,1) -> 121
A8: 출처 항목 | B8: =COUNTA('출처30'!A2:A31) -> 30
A9: 읽기 길이 검토 항목 | B9: =COUNTA('읽기점검'!A2:A6) -> 5
A12: 실제 인지단계 | B12: 문항 수 | C12: 비율
A13: L1 알아보기 | B13: =COUNTIF('문항240'!E2:E241,1) -> 69 | C13: =B13/$B$5 -> 0.2875
A14: L2 이어보기 | B14: =COUNTIF('문항240'!E2:E241,2) -> 52 | C14: =B14/$B$5 -> 0.21666667
A15: L3 자료읽기 | B15: =COUNTIF('문항240'!E2:E241,3) -> 104 | C15: =B15/$B$5 -> 0.43333333
A16: L4 따져보기 | B16: =COUNTIF('문항240'!E2:E241,4) -> 15 | C16: =B16/$B$5 -> 0.0625
A18: 학습 경로 | B18: L1 | C18: L2 | D18: L3 | E18: L4 | F18: 문항 수
A19: early | B19: 45 | C19: 15 | D19: 0 | E19: 0 | F19: =SUM(B19:E19) -> 60
A20: primary | B20: 26 | C20: 34 | D20: 0 | E20: 0 | F20: =SUM(B20:E20) -> 60
A21: upper | B21: 33 | C21: 21 | D21: 6 | E21: 0 | F21: =SUM(B21:E21) -> 60
A22: middle | B22: 17 | C22: 19 | D22: 22 | E22: 2 | F22: =SUM(B22:E22) -> 60
A23: high | B23: 11 | C23: 13 | D23: 34 | E23: 2 | F23: =SUM(B23:E23) -> 60
A24: adult | B24: 7 | C24: 12 | D24: 36 | E24: 5 | F24: =SUM(B24:E24) -> 60
A26: 난이도 1~4와 인지단계 L1~L4는 다릅니다. 네 번째 변형이라고 자동으로 L4를 부여하지 않았습니다.
A28: 질문·보기·해설·자료·원문 URL을 모두 수록했습니다. 원문 작성기관과 현대 공개기관이 다를 때 출처 시트에서 구분합니다.
A30: 이 파일은 검토용입니다. 사용자 기록·지도·서버를 수정하지 않습니다. 5건의 길이 참고 기준 초과는 읽기점검 시트에 그대로 남겼습니다.

Sheet 문항240
A1: ID | B1: old ID | C1: 단원 | D1: 난이도 | E1: 실제 인지단계 | F1: 질문 | G1: A | H1: B | I1: C | J1: D | K1: 정답 번호 | L1: 정답 이유 | M1: 남길 한 문장 | N1: familyId | O1: 출처 | P1: 질문+최장보기 글자수
A2: 920001 | B2: 910001 | C2: 독도는 어디에 있을까 | D2: 1 | E2: 1 | F2: 독도를 이루는 두 큰 섬의 이름은 무엇인가요? | G2: 동도와 서도 | H2: 울릉도와 동도 | I2: 제주도와 서도 | J2: 울릉도와 제주도 | K2: 1 | L2: 동도와 서도가 독도의 두 큰 섬이에요. 둘레에는 작은 바위섬들도 있어요. | M2: 독도는 동도·서도라는 두 큰 섬과 주변 바위섬들로 이루어져요. | N2: dk-composition | O2: 대한민국 외교부 · 독도의 구성 및 위치 https://dokdo.mofa.go.kr/kor/introduce/location.jsp | P2: =LEN(F2)+MAX(LEN(G2),LEN(H2),LEN(I2),LEN(J2)) -> 33
A3: 920002 | B3: 910002 | C3: 독도는 어디에 있을까 | D3: 2 | E3: 2 | F3: 독도의 두 큰 섬 주위에는 어떤 땅이 더 있나요? | G3: 작은 바위섬들 | H3: 울릉도 본섬 | I3: 일본의 오키섬 | K3: 1 | L3: 독도에는 동도·서도뿐 아니라 둘레의 작은 바위섬들도 포함돼요. | M3: 독도는 동도·서도라는 두 큰 섬과 주변 바위섬들로 이루어져요. | N3: dk-composition | O3: 대한민국 외교부 · 독도의 구성 및 위치 https://dokdo.mofa.go.kr/kor/introduce/location.jsp | P3: =LEN(F3)+MAX(LEN(G3),LEN(H3),LEN(I3),LEN(J3)) -> 34
A4: 920003 | B4: 910003 | C4: 독도는 어디에 있을까 | D4: 3 | E4: 3 | F4: 독도 안내판에 두 큰 섬만 그렸다면 어떤 땅을 추가해야 하나요? | G4: 울릉도 전체 | H4: 주변의 부속 바위섬 | I4: 일본 오키섬 전체 | K4: 2 | L4: 자료는 두 큰 섬과 주변 부속 도서를 함께 독도의 구성으로 설명해요. | M4: 독도는 동도·서도라는 두 큰 섬과 주변 바위섬들로 이루어져요. | N4: dk-composition | O4: 대한민국 외교부 · 독도의 구성 및 위치 https://dokdo.mofa.go.kr/kor/introduce/location.jsp | P4: =LEN(F4)+MAX(LEN(G4),LEN(H4),LEN(I4),LEN(J4)) -> 45
A5: 920004 | B5: 910004 | C5: 독도는 어디에 있을까 | D5: 4 | E5: 4 | F5: 독도를 ‘동도 한 섬의 이름’이라고 쓴 문장을 어떻게 고쳐야 하나요? | G5: 동도와 울릉도를 아우르는 이름이다 | H5: 서도 한 섬만 가리키는 이름이다 | I5: 동도·서도와 주변 바위섬을 아우르는 이름이다 | K5: 3 | L5: 동도는 독도의 일부예요. 독도라는 이름은 서도와 부속 도서도 아울러요. | M5: 독도는 동도·서도라는 두 큰 섬과 주변 바위섬들로 이루어져요. | N5: dk-composition | O5: 대한민국 외교부 · 독도의 구성 및 위치 https://dokdo.mofa.go.kr/kor/introduce/location.jsp | P5: =LEN(F5)+MAX(LEN(G5),LEN(H5),LEN(I5),LEN(J5)) -> 62
A6: 920005 | B6: 910005 | C6: 독도는 어디에 있을까 | D6: 1 | E6: 1 | F6: 독도는 울릉도에서 어느 방향에 있나요? | G6: 동북쪽 | H6: 동남쪽 | I6: 서남쪽 | J6: 서북쪽 | K6: 2 | L6: 울릉도에서 동쪽이면서 남쪽인 방향으로 가면 독도가 있어요. | M6: 독도는 울릉도에서 동남쪽으로 약 87.4km 떨어져 있어요. | N6: dk-relative-location | O6: 대한민국 해양수산부 · 독도의 주소와 위치 https://www.mof.go.kr/doc/ko/selectDoc.do?bbsSeq=27&docSeq=20937&menuSeq=929 대한민국 외교부 · 독도의 구성 및 위치 https://dokdo.mofa.go.kr/kor/introduce/location.jsp | P6: =LEN(F6)+MAX(LEN(G6),LEN(H6),LEN(I6),LEN(J6)) -> 24
A7: 920006 | B7: 910006 | C7: 독도는 어디에 있을까 | D7: 2 | E7: 1 | F7: 울릉도와 독도 사이의 거리는 약 얼마인가요? | G7: 157.5km | H7: 8.74km | I7: 87.4km | J7: 874km | K7: 3 | L7: 87.4km가 울릉도와 독도 사이 거리예요. | M7: 독도는 울릉도에서 동남쪽으로 약 87.4km 떨어져 있어요. | N7: dk-relative-location | O7: 대한민국 해양수산부 · 독도의 주소와 위치 https://www.mof.go.kr/doc/ko/selectDoc.do?bbsSeq=27&docSeq=20937&menuSeq=929 대한민국 외교부 · 독도의 구성 및 위치 https://dokdo.mofa.go.kr/kor/introduce/location.jsp | P7: =LEN(F7)+MAX(LEN(G7),LEN(H7),LEN(I7),LEN(J7)) -> 31
A8: 920007 | B8: 910007 | C8: 독도는 어디에 있을까 | D8: 3 | E8: 3 | F8: 거리표에서 독도에 더 가까운 곳은 어디인가요? | G8: 울릉도 | H8: 일본 오키섬 | K8: 1 | L8: 87.4km가 157.5km보다 짧으므로 울릉도가 더 가까워요. | M8: 독도는 울릉도에서 동남쪽으로 약 87.4km 떨어져 있어요. | N8: dk-relative-location | O8: 대한민국 해양수산부 · 독도의 주소와 위치 https://www.mof.go.kr/doc/ko/selectDoc.do?bbsSeq=27&docSeq=20937&menuSeq=929 대한민국 외교부 · 독도의 구성 및 위치 https://dokdo.mofa.go.kr/kor/introduce/location.jsp | P8: =LEN(F8)+MAX(LEN(G8),LEN(H8),LEN(I8),LEN(J8)) -> 31
A9: 920008 | B9: 910008 | C9: 독도는 어디에 있을까 | D9: 4 | E9: 3 | F9: 독도에서 울릉도까지는 오키섬까지보다 몇 km 더 가까운가요? | G9: 244.9km | H9: 87.4km | I9: 157.5km | J9: 70.1km | K9: 4 | L9: 두 거리를 빼면 157.5−87.4=70.1km예요. 울릉도가 그만큼 더 가까워요. | M9: 독도는 울릉도에서 동남쪽으로 약 87.4km 떨어져 있어요. | N9: dk-relative-location | O9: 대한민국 해양수산부 · 독도의 주소와 위치 https://www.mof.go.kr/doc/ko/selectDoc.do?bbsSeq=27&docSeq=20937&menuSeq=929 대한민국 외교부 · 독도의 구성 및 위치 https://dokdo.mofa.go.kr/kor/introduce/location.jsp | P9: =LEN(F9)+MAX(LEN(G9),LEN(H9),LEN(I9),LEN(J9)) -> 40
A10: 920009 | B10: 910009 | C10: 독도는 어디에 있을까 | D10: 1 | E10: 1 | F10: 독도의 동쪽에 있는 큰 섬은 무엇인가요? | G10: 서도 | H10: 동도 | K10: 2 | L10: 동도의 ‘동’은 동쪽을 뜻해요. 서도보다 동쪽에 있는 큰 섬이에요. | M10: 동도는 동쪽의 큰 섬이고, 서도는 서쪽의 큰 섬이에요. | N10: dk-orientation | O10: 대한민국 외교부 · 독도의 구성 및 위치 https://dokdo.mofa.go.kr/kor/introduce/location.jsp | P10: =LEN(F10)+MAX(LEN(G10),LEN(H10),LEN(I10),LEN(J10)) -> 24
A11: 920010 | B11: 910010 | C11: 독도는 어디에 있을까 | D11: 2 | E11: 2 | F11: 독도의 서쪽 큰 섬을 지도에 표시하려면 어떤 이름을 쓰나요? | G11: 서도 | H11: 동도 | K11: 1 | L11: 서쪽 큰 섬은 서도이고, 동쪽 큰 섬은 동도예요. | M11: 동도는 동쪽의 큰 섬이고, 서도는 서쪽의 큰 섬이에요. | N11: dk-orientation | O11: 대한민국 외교부 · 독도의 구성 및 위치 https://dokdo.mofa.go.kr/kor/introduce/location.jsp | P11: =LEN(F11)+MAX(LEN(G11),LEN(H11),LEN(I11),LEN(J11)) -> 35
A12: 920011 | B12: 910011 | C12: 독도는 어디에 있을까 | D12: 3 | E12: 3 | F12: 위치표에서 A에 넣을 섬 이름은 무엇인가요? | G12: 동도 | H12: 서도 | K12: 2 | L12: A는 서쪽 자리에 있으므로 서도예요. 오른쪽 동도와 짝을 이루어요. | M12: 동도는 동쪽의 큰 섬이고, 서도는 서쪽의 큰 섬이에요. | N12: dk-orientation | O12: 대한민국 외교부 · 독도의 구성 및 위치 https://dokdo.mofa.go.kr/kor/introduce/location.jsp | P12: =LEN(F12)+MAX(LEN(G12),LEN(H12),LEN(I12),LEN(J12)) -> 26
A13: 920012 | B13: 910012 | C13: 독도는 어디에 있을까 | D13: 4 | E13: 3 | F13: 동쪽 화살표가 왼쪽을 가리키는 위치표에서 동도는 어느 쪽에 놓이나요? | G13: 왼쪽 | H13: 오른쪽 | K13: 1 | L13: 이 위치표에서는 동쪽이 왼쪽이에요. 동쪽 섬인 동도도 왼쪽에 놓여요. | M13: 동도는 동쪽의 큰 섬이고, 서도는 서쪽의 큰 섬이에요. | N13: dk-orientation | O13: 대한민국 외교부 · 독도의 구성 및 위치 https://dokdo.mofa.go.kr/kor/introduce/location.jsp | P13: =LEN(F13)+MAX(LEN(G13),LEN(H13),LEN(I13),LEN(J13)) -> 41
A14: 920013 | B14: 910013 | C14: 독도는 어디에 있을까 | D14: 1 | E14: 1 | F14: 울릉도에서 독도를 보기 좋은 날씨는 무엇인가요? | G14: 맑고 시야가 트인 날 | H14: 짙은 안개가 낀 날 | I14: 앞이 흐릴 만큼 비가 오는 날 | K14: 1 | L14: 맑고 시야가 트여야 멀리 있는 독도를 볼 수 있어요. | M14: 울릉도에서는 날씨가 맑고 시야가 좋을 때 독도를 볼 수 있어요. | N14: dk-visibility | O14: 대한민국 외교부 자료실 · 세종실록 지리지(1454) https://dokdo.mofa.go.kr/kor/pds/part06_view02.jsp 대한민국 외교부 · 독도의 구성 및 위치 https://dokdo.mofa.go.kr/kor/introduce/location.jsp | P14: =LEN(F14)+MAX(LEN(G14),LEN(H14),LEN(I14),LEN(J14)) -> 42
A15: 920014 | B15: 910014 | C15: 독도는 어디에 있을까 | D15: 2 | E15: 2 | F15: 울릉도에서 먼 독도를 보려면 어떤 대기 조건이 필요한가요? | G15: 짙은 안개가 바다를 덮음 | H15: 안개가 적고 시야가 맑음 | I15: 비가 강하게 내려 시야가 흐림 | K15: 2 | L15: 멀리 있는 섬을 보려면 시야를 가리는 안개 등이 적어야 해요. | M15: 울릉도에서는 날씨가 맑고 시야가 좋을 때 독도를 볼 수 있어요. | N15: dk-visibility | O15: 대한민국 외교부 자료실 · 세종실록 지리지(1454) https://dokdo.mofa.go.kr/kor/pds/part06_view02.jsp 대한민국 외교부 · 독도의 구성 및 위치 https://dokdo.mofa.go.kr/kor/introduce/location.jsp | P15: =LEN(F15)+MAX(LEN(G15),LEN(H15),LEN(I15),LEN(J15)) -> 48
A16: 920015 | B16: 910015 | C16: 독도는 어디에 있을까 | D16: 3 | E16: 3 | F16: 세종실록 지리지는 두 섬이 보이는 날씨를 어떻게 설명하나요? | G16: 짙은 안개가 낄 때 | H16: 계절에 상관없이 모든 날 | I16: 날씨가 맑을 때 | K16: 3 | L16: 역문은 날씨가 맑으면 바라볼 수 있다고 설명해요. | M16: 울릉도에서는 날씨가 맑고 시야가 좋을 때 독도를 볼 수 있어요. | N16: dk-visibility | O16: 대한민국 외교부 자료실 · 세종실록 지리지(1454) https://dokdo.mofa.go.kr/kor/pds/part06_view02.jsp 대한민국 외교부 · 독도의 구성 및 위치 https://dokdo.mofa.go.kr/kor/introduce/location.jsp | P16: =LEN(F16)+MAX(LEN(G16),LEN(H16),LEN(I16),LEN(J16)) -> 46
A17: 920016 | B17: 910016 | C17: 독도는 어디에 있을까 | D17: 4 | E17: 3 | F17: 두 관찰일 중 울릉도에서 독도를 보기 더 좋은 날은 언제인가요? | G17: B일 | H17: A일 | K17: 2 | L17: A일은 시야가 맑아 멀리 있는 독도를 바라보기에 더 적합해요. | M17: 울릉도에서는 날씨가 맑고 시야가 좋을 때 독도를 볼 수 있어요. | N17: dk-visibility | O17: 대한민국 외교부 자료실 · 세종실록 지리지(1454) https://dokdo.mofa.go.kr/kor/pds/part06_view02.jsp 대한민국 외교부 · 독도의 구성 및 위치 https://dokdo.mofa.go.kr/kor/introduce/location.jsp | P17: =LEN(F17)+MAX(LEN(G17),LEN(H17),LEN(I17),LEN(J17)) -> 37
A18: 920017 | B18: 910017 | C18: 독도는 어디에 있을까 | D18: 1 | E18: 1 | F18: 독도의 부속 도서 89개를 셀 때 따로 구분하는 두 큰 섬은 무엇인가요? | G18: 동도와 서도 | H18: 울릉도와 독도 | I18: 동도와 울릉도 | K18: 1 | L18: 부속 도서 89개에 동도와 서도 두 큰 섬을 따로 더해 구성해요. | M18: 독도의 부속 도서 89개는 동도와 서도를 뺀 작은 섬들의 수예요. | N18: dk-islet-count | O18: 대한민국 외교부 · 독도의 구성 및 위치 https://dokdo.mofa.go.kr/kor/introduce/location.jsp 대한민국 한국해양과학기술원 · 독도 위치 및 규모 https://www.dokdo.re.kr/home/cms/cmsCont.do?cntnts_sn=64 | P18: =LEN(F18)+MAX(LEN(G18),LEN(H18),LEN(I18),LEN(J18)) -> 47
A19: 920018 | B19: 910018 | C19: 독도는 어디에 있을까 | D19: 2 | E19: 2 | F19: 동도·서도와 부속 도서 89개를 합하면 몇 개인가요? | G19: 91개 | H19: 89개 | I19: 90개 | J19: 93개 | K19: 1 | L19: 두 큰 섬 2개와 부속 도서 89개를 더하면 91개예요. | M19: 독도의 부속 도서 89개는 동도와 서도를 뺀 작은 섬들의 수예요. | N19: dk-islet-count | O19: 대한민국 외교부 · 독도의 구성 및 위치 https://dokdo.mofa.go.kr/kor/introduce/location.jsp 대한민국 한국해양과학기술원 · 독도 위치 및 규모 https://www.dokdo.re.kr/home/cms/cmsCont.do?cntnts_sn=64 | P19: =LEN(F19)+MAX(LEN(G19),LEN(H19),LEN(I19),LEN(J19)) -> 32
A20: 920019 | B20: 910019 | C20: 독도는 어디에 있을까 | D20: 3 | E20: 3 | F20: 면적표에서 부속 도서 전체의 넓이는 얼마인가요? | G20: 73,297㎡ | H20: 25,517㎡ | I20: 88,740㎡ | J20: 187,554㎡ | K20: 2 | L20: 부속 도서 행의 값이 25,517㎡예요. 전체 면적이나 큰 섬 하나의 면적과 구분해요. | M20: 독도의 부속 도서 89개는 동도와 서도를 뺀 작은 섬들의 수예요. | N20: dk-islet-count | O20: 대한민국 외교부 · 독도의 구성 및 위치 https://dokdo.mofa.go.kr/kor/introduce/location.jsp 대한민국 한국해양과학기술원 · 독도 위치 및 규모 https://www.dokdo.re.kr/home/cms/cmsCont.do?cntnts_sn=64 | P20: =LEN(F20)+MAX(LEN(G20),LEN(H20),LEN(I20),LEN(J20)) -> 34
A21: 920020 | B21: 910020 | C21: 독도는 어디에 있을까 | D21: 4 | E21: 3 | F21: 독도 전체 면적을 동도와 서도 면적만 더해 계산하면 무엇이 빠지나요? | G21: 두 섬 사이 바다 25,517㎡ | H21: 부속 도서 25,517㎡ | I21: 울릉도 25,517㎡ | K21: 2 | L21: 187,554−73,297−88,740=25,517㎡예요. 빠진 값은 부속 도서의 땅 면적이에요. | M21: 독도의 부속 도서 89개는 동도와 서도를 뺀 작은 섬들의 수예요. | N21: dk-islet-count | O21: 대한민국 외교부 · 독도의 구성 및 위치 https://dokdo.mofa.go.kr/kor/introduce/location.jsp 대한민국 한국해양과학기술원 · 독도 위치 및 규모 https://www.dokdo.re.kr/home/cms/cmsCont.do?cntnts_sn=64 | P21: =LEN(F21)+MAX(LEN(G21),LEN(H21),LEN(I21),LEN(J21)) -> 55
A22: 920021 | B22: 910021 | C22: 동도와 서도 비교 | D22: 1 | E22: 1 | F22: 독도의 두 큰 섬 중 더 높은 섬은 무엇인가요? | G22: 서도 | H22: 동도 | K22: 1 | L22: 서도의 최고 높이는 168.5m로 동도의 98.6m보다 높아요. | M22: 독도에서 더 높은 큰 섬은 서도예요. 서도는 168.5m, 동도는 98.6m예요. | N22: dk-heights | O22: 대한민국 외교부 · 독도의 구성 및 위치 https://dokdo.mofa.go.kr/kor/introduce/location.jsp 대한민국 한국해양과학기술원 · 독도 위치 및 규모 https://www.dokdo.re.kr/home/cms/cmsCont.do?cntnts_sn=64 | P22: =LEN(F22)+MAX(LEN(G22),LEN(H22),LEN(I22),LEN(J22)) -> 28
A23: 920022 | B23: 910022 | C23: 동도와 서도 비교 | D23: 2 | E23: 2 | F23: 독도에서 최고 높이가 98.6m인 큰 섬은 무엇인가요? | G23: 서도 | H23: 동도 | K23: 2 | L23: 98.6m는 동도의 최고 높이예요. 서도의 값과 구분해요. | M23: 독도에서 더 높은 큰 섬은 서도예요. 서도는 168.5m, 동도는 98.6m예요. | N23: dk-heights | O23: 대한민국 외교부 · 독도의 구성 및 위치 https://dokdo.mofa.go.kr/kor/introduce/location.jsp 대한민국 한국해양과학기술원 · 독도 위치 및 규모 https://www.dokdo.re.kr/home/cms/cmsCont.do?cntnts_sn=64 | P23: =LEN(F23)+MAX(LEN(G23),LEN(H23),LEN(I23),LEN(J23)) -> 32
A24: 920023 | B24: 910023 | C24: 동도와 서도 비교 | D24: 3 | E24: 3 | F24: 높이표에 따르면 서도는 동도보다 몇 m 더 높은가요? | G24: 267.1m | H24: 98.6m | I24: 69.9m | J24: 151m | K24: 3 | L24: 168.5−98.6=69.9m예요. 두 최고 높이를 같은 단위로 빼요. | M24: 독도에서 더 높은 큰 섬은 서도예요. 서도는 168.5m, 동도는 98.6m예요. | N24: dk-heights | O24: 대한민국 외교부 · 독도의 구성 및 위치 https://dokdo.mofa.go.kr/kor/introduce/location.jsp 대한민국 한국해양과학기술원 · 독도 위치 및 규모 https://www.dokdo.re.kr/home/cms/cmsCont.do?cntnts_sn=64 | P24: =LEN(F24)+MAX(LEN(G24),LEN(H24),LEN(I24),LEN(J24)) -> 35
A25: 920024 | B25: 910024 | C25: 동도와 서도 비교 | D25: 4 | E25: 3 | F25: 표의 높이를 기준으로 100m보다 높은 곳이 있는 섬은 어디인가요? | G25: 동도만 | H25: 두 섬 모두 | I25: 어느 섬도 없음 | J25: 서도만 | K25: 4 | L25: 서도는 168.5m까지 올라가지만 동도의 최고점은 98.6m예요. 동도에 100m 지점을 표시하면 최고 높이를 넘어요. | M25: 독도에서 더 높은 큰 섬은 서도예요. 서도는 168.5m, 동도는 98.6m예요. | N25: dk-heights | O25: 대한민국 외교부 · 독도의 구성 및 위치 https://dokdo.mofa.go.kr/kor/introduce/location.jsp 대한민국 한국해양과학기술원 · 독도 위치 및 규모 https://www.dokdo.re.kr/home/cms/cmsCont.do?cntnts_sn=64 | P25: =LEN(F25)+MAX(LEN(G25),LEN(H25),LEN(I25),LEN(J25)) -> 45
A26: 920025 | B26: 910025 | C26: 동도와 서도 비교 | D26: 1 | E26: 1 | F26: 독도의 두 큰 섬 중 땅의 넓이가 더 넓은 섬은 무엇인가요? | G26: 서도 | H26: 동도 | K26: 1 | L26: 서도는 88,740㎡, 동도는 73,297㎡이므로 서도가 더 넓어요. | M26: 서도는 동도보다 면적이 넓지만, 해안선의 둘레는 동도가 더 길어요. | N26: dk-area | O26: 대한민국 외교부 · 독도의 구성 및 위치 https://dokdo.mofa.go.kr/kor/introduce/location.jsp 대한민국 한국해양과학기술원 · 독도 위치 및 규모 https://www.dokdo.re.kr/home/cms/cmsCont.do?cntnts_sn=64 | P26: =LEN(F26)+MAX(LEN(G26),LEN(H26),LEN(I26),LEN(J26)) -> 35
A27: 920026 | B27: 910026 | C27: 동도와 서도 비교 | D27: 2 | E27: 2 | F27: 독도 면적표의 ㎡는 무엇을 나타내는 단위인가요? | G27: 봉우리의 높이 | H27: 해안선을 따라 잰 길이 | I27: 땅의 넓이 | K27: 3 | L27: 제곱미터는 넓이를 나타내요. 섬의 높이를 나타내는 미터와 달라요. | M27: 서도는 동도보다 면적이 넓지만, 해안선의 둘레는 동도가 더 길어요. | N27: dk-area | O27: 대한민국 외교부 · 독도의 구성 및 위치 https://dokdo.mofa.go.kr/kor/introduce/location.jsp 대한민국 한국해양과학기술원 · 독도 위치 및 규모 https://www.dokdo.re.kr/home/cms/cmsCont.do?cntnts_sn=64 | P27: =LEN(F27)+MAX(LEN(G27),LEN(H27),LEN(I27),LEN(J27)) -> 38
A28: 920027 | B28: 910027 | C28: 동도와 서도 비교 | D28: 3 | E28: 3 | F28: 표에서 해안선의 둘레가 더 긴 큰 섬은 어디인가요? | G28: 서도 | H28: 동도 | K28: 2 | L28: 동도 둘레는 2.8km, 서도는 2.6km예요. 둘레를 비교하면 동도가 더 길어요. | M28: 서도는 동도보다 면적이 넓지만, 해안선의 둘레는 동도가 더 길어요. | N28: dk-area | O28: 대한민국 외교부 · 독도의 구성 및 위치 https://dokdo.mofa.go.kr/kor/introduce/location.jsp 대한민국 한국해양과학기술원 · 독도 위치 및 규모 https://www.dokdo.re.kr/home/cms/cmsCont.do?cntnts_sn=64 | P28: =LEN(F28)+MAX(LEN(G28),LEN(H28),LEN(I28),LEN(J28)) -> 30
A29: 920028 | B29: 910028 | C29: 동도와 서도 비교 | D29: 4 | E29: 3 | F29: 표에 맞게 서도와 동도의 면적·둘레를 함께 비교한 것은 무엇인가요? | G29: 서도는 더 넓고, 동도는 둘레가 더 길다 | H29: 서도가 더 넓으므로 둘레도 더 길다 | I29: 동도가 더 넓고 둘레도 더 길다 | K29: 1 | L29: 넓이와 둘레는 서로 다른 값이에요. 표에서는 두 항목에서 더 큰 섬이 서로 달라요. | M29: 서도는 동도보다 면적이 넓지만, 해안선의 둘레는 동도가 더 길어요. | N29: dk-area | O29: 대한민국 외교부 · 독도의 구성 및 위치 https://dokdo.mofa.go.kr/kor/introduce/location.jsp 대한민국 한국해양과학기술원 · 독도 위치 및 규모 https://www.dokdo.re.kr/home/cms/cmsCont.do?cntnts_sn=64 | P29: =LEN(F29)+MAX(LEN(G29),LEN(H29),LEN(I29),LEN(J29)) -> 59
A30: 920029 | B30: 910029 | C30: 동도와 서도 비교 | D30: 1 | E30: 1 | F30: 동도와 서도는 무엇을 사이에 두고 떨어져 있나요? | G30: 육지 도로 | H30: 바다 | I30: 강 | K30: 2 | L30: 두 섬의 물 위 육지는 바다를 사이에 두고 떨어져 있어요. | M30: 동도와 서도의 가장 가까운 해안 사이 거리는 약 151m예요. | N30: dk-shore-gap | O30: 대한민국 한국해양과학기술원 · 독도 지형 및 지질 https://www.dokdo.re.kr/home/cms/cmsCont.do?cntnts_sn=66 대한민국 국가유산청 · 독도 천연보호구역 https://www.heritage.go.kr/heri/cul/culSelectDetail.do?VdkVgwKey=16%2C03360000%2C37&pageNo=1_1_2_0 | P30: =LEN(F30)+MAX(LEN(G30),LEN(H30),LEN(I30),LEN(J30)) -> 32
A31: 920030 | B31: 910030 | C31: 동도와 서도 비교 | D31: 2 | E31: 2 | F31: 동도와 서도의 가장 가까운 해안 사이 거리는 약 얼마인가요? | G31: 151m | H31: 87.4km | I31: 98.6m | J31: 168.5m | K31: 1 | L31: 약 151m는 두 큰 섬의 가장 가까운 해안 사이 간격이에요. | M31: 동도와 서도의 가장 가까운 해안 사이 거리는 약 151m예요. | N31: dk-shore-gap | O31: 대한민국 한국해양과학기술원 · 독도 지형 및 지질 https://www.dokdo.re.kr/home/cms/cmsCont.do?cntnts_sn=66 대한민국 국가유산청 · 독도 천연보호구역 https://www.heritage.go.kr/heri/cul/culSelectDetail.do?VdkVgwKey=16%2C03360000%2C37&pageNo=1_1_2_0 | P31: =LEN(F31)+MAX(LEN(G31),LEN(H31),LEN(I31),LEN(J31)) -> 39
A32: 920031 | B32: 910031 | C32: 동도와 서도 비교 | D32: 3 | E32: 3 | F32: 151m라는 간격을 지도에 표시할 때 양 끝은 어디에 두어야 하나요? | G32: 두 섬의 정상 | H32: 등대와 주민숙소 | I32: 서로 가장 가까운 두 해안 | K32: 3 | L32: 151m는 가장 가까운 해안 사이 거리이므로 그 두 지점을 연결해요. | M32: 동도와 서도의 가장 가까운 해안 사이 거리는 약 151m예요. | N32: dk-shore-gap | O32: 대한민국 한국해양과학기술원 · 독도 지형 및 지질 https://www.dokdo.re.kr/home/cms/cmsCont.do?cntnts_sn=66 대한민국 국가유산청 · 독도 천연보호구역 https://www.heritage.go.kr/heri/cul/culSelectDetail.do?VdkVgwKey=16%2C03360000%2C37&pageNo=1_1_2_0 | P32: =LEN(F32)+MAX(LEN(G32),LEN(H32),LEN(I32),LEN(J32)) -> 52
A33: 920032 | B33: 910032 | C33: 동도와 서도 비교 | D33: 4 | E33: 3 | F33: 축척이 1cm당 50m인 지도에서 151m 간격은 약 몇 cm인가요? | G33: 7,550cm | H33: 3.02cm | I33: 151cm | J33: 0.302cm | K33: 2 | L33: 151÷50=3.02cm예요. 실제 간격을 1cm가 나타내는 거리로 나누어요. | M33: 동도와 서도의 가장 가까운 해안 사이 거리는 약 151m예요. | N33: dk-shore-gap | O33: 대한민국 한국해양과학기술원 · 독도 지형 및 지질 https://www.dokdo.re.kr/home/cms/cmsCont.do?cntnts_sn=66 대한민국 국가유산청 · 독도 천연보호구역 https://www.heritage.go.kr/heri/cul/culSelectDetail.do?VdkVgwKey=16%2C03360000%2C37&pageNo=1_1_2_0 | P33: =LEN(F33)+MAX(LEN(G33),LEN(H33),LEN(I33),LEN(J33)) -> 45
A34: 920033 | B34: 910033 | C34: 동도와 서도 비교 | D34: 1 | E34: 1 | F34: 독도에서 가파른 봉우리가 두드러지는 큰 섬은 무엇인가요? | G34: 서도 | H34: 동도 | K34: 1 | L34: 서도는 높고 가파르게 솟은 봉우리의 모습이 두드러져요. | M34: 서도는 가파르게 솟고, 동도는 정상 부근에 비교적 평탄한 공간이 있어요. | N34: dk-terrain-contrast | O34: 대한민국 국가유산청 · 독도 천연보호구역 https://www.heritage.go.kr/heri/cul/culSelectDetail.do?VdkVgwKey=16%2C03360000%2C37&pageNo=1_1_2_0 대한민국 전북교육청 · 독도 사진 자료 https://www.jbe.go.kr/dokdo/assets/sub/picture.html | P34: =LEN(F34)+MAX(LEN(G34),LEN(H34),LEN(I34),LEN(J34)) -> 33
A35: 920034 | B35: 910034 | C35: 동도와 서도 비교 | D35: 2 | E35: 2 | F35: 독도의 헬기장 등 시설이 자리한 비교적 평탄한 상부는 어느 섬에 있나요? | G35: 서도 | H35: 동도 | K35: 2 | L35: 동도 상부의 비교적 평탄한 곳에는 헬기장과 여러 시설이 있어요. | M35: 서도는 가파르게 솟고, 동도는 정상 부근에 비교적 평탄한 공간이 있어요. | N35: dk-terrain-contrast | O35: 대한민국 국가유산청 · 독도 천연보호구역 https://www.heritage.go.kr/heri/cul/culSelectDetail.do?VdkVgwKey=16%2C03360000%2C37&pageNo=1_1_2_0 대한민국 전북교육청 · 독도 사진 자료 https://www.jbe.go.kr/dokdo/assets/sub/picture.html | P35: =LEN(F35)+MAX(LEN(G35),LEN(H35),LEN(I35),LEN(J35)) -> 42
A36: 920035 | B36: 910035 | C36: 동도와 서도 비교 | D36: 3 | E36: 3 | F36: 지형 설명 A는 동도와 서도 중 어느 섬인가요? | G36: 동도 | H36: 서도 | K36: 1 | L36: A는 정상 부근이 비교적 평탄하고 시설이 있는 섬이므로 동도예요. | M36: 서도는 가파르게 솟고, 동도는 정상 부근에 비교적 평탄한 공간이 있어요. | N36: dk-terrain-contrast | O36: 대한민국 국가유산청 · 독도 천연보호구역 https://www.heritage.go.kr/heri/cul/culSelectDetail.do?VdkVgwKey=16%2C03360000%2C37&pageNo=1_1_2_0 대한민국 전북교육청 · 독도 사진 자료 https://www.jbe.go.kr/dokdo/assets/sub/picture.html | P36: =LEN(F36)+MAX(LEN(G36),LEN(H36),LEN(I36),LEN(J36)) -> 28
A37: 920036 | B37: 910036 | C37: 동도와 서도 비교 | D37: 4 | E37: 4 | F37: 독도 모형에서 동도를 서도와 똑같은 뾰족한 산으로 만들었다면 무엇을 고쳐야 하나요? | G37: 동도 상부의 비교적 평탄한 공간을 살린다 | H37: 동도를 서도보다 더 높게 만든다 | I37: 동도의 해안 절벽을 모두 없앤다 | K37: 1 | L37: 두 섬의 차이를 보여주려면 동도의 낮은 상부 공간과 주변 절벽을 함께 표현해야 해요. | M37: 서도는 가파르게 솟고, 동도는 정상 부근에 비교적 평탄한 공간이 있어요. | N37: dk-terrain-contrast | O37: 대한민국 국가유산청 · 독도 천연보호구역 https://www.heritage.go.kr/heri/cul/culSelectDetail.do?VdkVgwKey=16%2C03360000%2C37&pageNo=1_1_2_0 대한민국 전북교육청 · 독도 사진 자료 https://www.jbe.go.kr/dokdo/assets/sub/picture.html | P37: =LEN(F37)+MAX(LEN(G37),LEN(H37),LEN(I37),LEN(J37)) -> 68
A38: 920037 | B38: 910037 | C38: 동도와 서도 비교 | D38: 1 | E38: 1 | F38: 동도와 서도 아래 바닷속에도 독도의 지형이 이어지나요? | G38: 해수면에서 끝나요 | H38: 바닷속으로 이어져요 | K38: 2 | L38: 동도·서도는 해저 화산체의 일부가 물 위로 드러난 모습이에요. | M38: 동도·서도는 큰 해저 화산체에서 바다 위로 드러난 일부예요. | N38: dk-above-below | O38: 대한민국 한국해양과학기술원 · 독도 지형 및 지질 https://www.dokdo.re.kr/home/cms/cmsCont.do?cntnts_sn=66 | P38: =LEN(F38)+MAX(LEN(G38),LEN(H38),LEN(I38),LEN(J38)) -> 40
A39: 920038 | B39: 910038 | C39: 동도와 서도 비교 | D39: 2 | E39: 2 | F39: 독도의 두 큰 섬은 무엇의 일부가 바다 위로 드러난 것인가요? | G39: 강이 쌓은 삼각주 | H39: 해저 화산체 | I39: 산호가 쌓인 산호섬 | K39: 2 | L39: 바닷속 화산활동으로 자란 화산체의 윗부분이 바다 위에서 보여요. | M39: 동도·서도는 큰 해저 화산체에서 바다 위로 드러난 일부예요. | N39: dk-above-below | O39: 대한민국 한국해양과학기술원 · 독도 지형 및 지질 https://www.dokdo.re.kr/home/cms/cmsCont.do?cntnts_sn=66 | P39: =LEN(F39)+MAX(LEN(G39),LEN(H39),LEN(I39),LEN(J39)) -> 44
A40: 920039 | B40: 910039 | C40: 동도와 서도 비교 | D40: 3 | E40: 3 | F40: 독도 설명의 약 2,300m는 어디서부터 잰 규모인가요? | G40: 해수면부터 서도 정상까지 | H40: 해수면부터 동도 정상까지 | I40: 바닷속 화산체의 기저부부터 | K40: 3 | L40: 약 2,300m는 해저 기저부부터 화산체 전체를 본 높이예요. | M40: 동도·서도는 큰 해저 화산체에서 바다 위로 드러난 일부예요. | N40: dk-above-below | O40: 대한민국 한국해양과학기술원 · 독도 지형 및 지질 https://www.dokdo.re.kr/home/cms/cmsCont.do?cntnts_sn=66 | P40: =LEN(F40)+MAX(LEN(G40),LEN(H40),LEN(I40),LEN(J40)) -> 45
...

Sheet 보기해설711
A1: ID | B1: choice ID | C1: 보기 | D1: 정답 여부 | E1: 보기별 해설 | F1: English choice | G1: English feedback
A2: 920001 | B2: a | C2: 동도와 서도 | D2: 1 | E2: 동도와 서도가 독도의 두 큰 섬이에요. 둘레에는 작은 바위섬들도 있어요. | F2: Dongdo and Seodo | G2: Dongdo and Seodo are the two main islands, surrounded by smaller islets.
A3: 920001 | B3: b | C3: 울릉도와 동도 | D3: 0 | E3: 동도는 맞지만 울릉도는 독도에서 떨어진 별개의 섬이에요. 다른 큰 섬은 서도예요. | F3: Ulleungdo and Dongdo | G3: Dongdo belongs to Dokdo, but Ulleungdo is a separate island. The other main island is Seodo.
A4: 920001 | B4: c | C4: 제주도와 서도 | D4: 0 | E4: 서도는 맞지만 제주도는 독도를 이루는 섬이 아니에요. 서도와 짝을 이루는 큰 섬은 동도예요. | F4: Jejudo and Seodo | G4: Seodo belongs to Dokdo, but Jejudo does not. Its other main island is Dongdo.
A5: 920001 | B5: d | C5: 울릉도와 제주도 | D5: 0 | E5: 울릉도와 제주도는 모두 독도와 별개의 섬이에요. 독도의 두 큰 섬은 동도와 서도예요. | F5: Ulleungdo and Jejudo | G5: Both are separate from Dokdo. Dokdo’s main islands are Dongdo and Seodo.
A6: 920002 | B6: a | C6: 작은 바위섬들 | D6: 1 | E6: 독도에는 동도·서도뿐 아니라 둘레의 작은 바위섬들도 포함돼요. | F6: Smaller rocky islets | G6: Dokdo includes the surrounding rocky islets as well as Dongdo and Seodo.
A7: 920002 | B7: b | C7: 울릉도 본섬 | D7: 0 | E7: 울릉도는 독도 주변의 부속 바위섬이 아니라 별개의 섬이에요. | F7: The main island of Ulleungdo | G7: Ulleungdo is a separate island, not one of Dokdo’s associated islets.
A8: 920002 | B8: c | C8: 일본의 오키섬 | D8: 0 | E8: 오키섬은 독도의 부속 섬이 아니라 일본에 있는 별개의 섬들이에요. | F8: Japan’s Oki Islands | G8: The Oki Islands are in Japan and are not part of Dokdo.
A9: 920003 | B9: b | C9: 울릉도 전체 | D9: 0 | E9: 울릉도는 독도 구성 목록에 들어 있지 않아요. 주변 부속 바위섬을 더해야 해요. | F9: All of Ulleungdo | G9: Ulleungdo is not part of the listed land area. The missing land is the associated islets.
A10: 920003 | B10: a | C10: 주변의 부속 바위섬 | D10: 1 | E10: 자료는 두 큰 섬과 주변 부속 도서를 함께 독도의 구성으로 설명해요. | F10: The surrounding associated islets | G10: The description includes the associated islets as well as the two main islands.
A11: 920003 | B11: c | C11: 일본 오키섬 전체 | D11: 0 | E11: 오키섬은 독도를 이루는 섬이 아니므로 이 구성도에 더하지 않아요. | F11: All of Japan’s Oki Islands | G11: The Oki Islands do not form part of Dokdo.
A12: 920004 | B12: b | C12: 동도와 울릉도를 아우르는 이름이다 | D12: 0 | E12: 울릉도는 독도와 별개의 섬이므로 구성에 넣으면 안 돼요. | F12: It names Dongdo and Ulleungdo | G12: Ulleungdo is separate and should not be added to Dokdo’s composition.
A13: 920004 | B13: c | C13: 서도 한 섬만 가리키는 이름이다 | D13: 0 | E13: 서도만으로 바꾸어도 여전히 동도와 주변 바위섬을 빠뜨려요. | F13: It names Seodo alone | G13: Changing the answer to Seodo alone still omits Dongdo and the smaller islets.
... A712: 920240 | B712: a | C712: 두 큰 섬과 부속 도서가 있고, 해저 화산활동으로 형성되었다 | D712: 1 | E712: 구성과 형성 원인이 모두 자료와 맞아요. | F712: It has two main islands and associated islets and formed through submarine volcanism | G712: Both the composition and origin match the sources.

Sheet 자료와출처
A1: ID | B1: 질문 | C1: 자료 필수 | D1: 먼저 알아둘 배경 | E1: 문항에 보이는 자료 | F1: 자료 범위·해석 표시 | G1: 근거 위치 | H1: 출처
A2: 920001 | B2: 독도를 이루는 두 큰 섬의 이름은 무엇인가요? | C2: 0 | G2: location: 두 큰 섬·부속 도서 / 높이·면적 / 울릉도·오키섬 거리 | H2: 대한민국 외교부 · 독도의 구성 및 위치 https://dokdo.mofa.go.kr/kor/introduce/location.jsp
A3: 920002 | B3: 독도의 두 큰 섬 주위에는 어떤 땅이 더 있나요? | C3: 0 | G3: location: 두 큰 섬·부속 도서 / 높이·면적 / 울릉도·오키섬 거리 | H3: 대한민국 외교부 · 독도의 구성 및 위치 https://dokdo.mofa.go.kr/kor/introduce/location.jsp
A4: 920003 | B4: 독도 안내판에 두 큰 섬만 그렸다면 어떤 땅을 추가해야 하나요? | C4: 1 | E4: 독도의 구성: 동도 + 서도 + 주변 부속 도서 89개. 부속 도서는 두 큰 섬 주변의 작은 섬들이에요. | G4: location: 두 큰 섬·부속 도서 / 높이·면적 / 울릉도·오키섬 거리 | H4: 대한민국 외교부 · 독도의 구성 및 위치 https://dokdo.mofa.go.kr/kor/introduce/location.jsp
A5: 920004 | B5: 독도를 ‘동도 한 섬의 이름’이라고 쓴 문장을 어떻게 고쳐야 하나요? | C5: 1 | E5: 구성 자료에는 동도·서도와 89개 부속 도서가 모두 독도에 포함된다고 나와 있어요. | G5: location: 두 큰 섬·부속 도서 / 높이·면적 / 울릉도·오키섬 거리 | H5: 대한민국 외교부 · 독도의 구성 및 위치 https://dokdo.mofa.go.kr/kor/introduce/location.jsp
A6: 920005 | B6: 독도는 울릉도에서 어느 방향에 있나요? | C6: 0 | G6: address: 동도·서도의 도로명 주소와 위치; 2018년 등록 자료, 2026-09-11 대조 location: 두 큰 섬·부속 도서 / 높이·면적 / 울릉도·오키섬 거리 | H6: 대한민국 해양수산부 · 독도의 주소와 위치 https://www.mof.go.kr/doc/ko/selectDoc.do?bbsSeq=27&docSeq=20937&menuSeq=929 대한민국 외교부 · 독도의 구성 및 위치 https://dokdo.mofa.go.kr/kor/introduce/location.jsp
A7: 920006 | B7: 울릉도와 독도 사이의 거리는 약 얼마인가요? | C7: 0 | G7: address: 동도·서도의 도로명 주소와 위치; 2018년 등록 자료, 2026-09-11 대조 location: 두 큰 섬·부속 도서 / 높이·면적 / 울릉도·오키섬 거리 | H7: 대한민국 해양수산부 · 독도의 주소와 위치 https://www.mof.go.kr/doc/ko/selectDoc.do?bbsSeq=27&docSeq=20937&menuSeq=929 대한민국 외교부 · 독도의 구성 및 위치 https://dokdo.mofa.go.kr/kor/introduce/location.jsp
A8: 920007 | B8: 거리표에서 독도에 더 가까운 곳은 어디인가요? | C8: 1 | E8: 독도에서 울릉도: 87.4km 독도에서 일본 오키섬: 157.5km | G8: address: 동도·서도의 도로명 주소와 위치; 2018년 등록 자료, 2026-09-11 대조 location: 두 큰 섬·부속 도서 / 높이·면적 / 울릉도·오키섬 거리 | H8: 대한민국 해양수산부 · 독도의 주소와 위치 https://www.mof.go.kr/doc/ko/selectDoc.do?bbsSeq=27&docSeq=20937&menuSeq=929 대한민국 외교부 · 독도의 구성 및 위치 https://dokdo.mofa.go.kr/kor/introduce/location.jsp
A9: 920008 | B9: 독도에서 울릉도까지는 오키섬까지보다 몇 km 더 가까운가요? | C9: 1 | E9: 독도–울릉도 87.4km, 독도–일본 오키섬 157.5km. 이 수치로 거리의 차이를 계산하세요. | G9: address: 동도·서도의 도로명 주소와 위치; 2018년 등록 자료, 2026-09-11 대조 location: 두 큰 섬·부속 도서 / 높이·면적 / 울릉도·오키섬 거리 | H9: 대한민국 해양수산부 · 독도의 주소와 위치 https://www.mof.go.kr/doc/ko/selectDoc.do?bbsSeq=27&docSeq=20937&menuSeq=929 대한민국 외교부 · 독도의 구성 및 위치 https://dokdo.mofa.go.kr/kor/introduce/location.jsp
A10: 920009 | B10: 독도의 동쪽에 있는 큰 섬은 무엇인가요? | C10: 0 | F10: 방향을 단순화한 위치 관계이며 두 섬의 실제 해안선을 그린 지도가 아니에요. | G10: location: 두 큰 섬·부속 도서 / 높이·면적 / 울릉도·오키섬 거리 | H10: 대한민국 외교부 · 독도의 구성 및 위치 https://dokdo.mofa.go.kr/kor/introduce/location.jsp
A11: 920010 | B11: 독도의 서쪽 큰 섬을 지도에 표시하려면 어떤 이름을 쓰나요? | C11: 0 | F11: 방향을 단순화한 위치 관계이며 두 섬의 실제 해안선을 그린 지도가 아니에요. | G11: location: 두 큰 섬·부속 도서 / 높이·면적 / 울릉도·오키섬 거리 | H11: 대한민국 외교부 · 독도의 구성 및 위치 https://dokdo.mofa.go.kr/kor/introduce/location.jsp
A12: 920011 | B12: 위치표에서 A에 넣을 섬 이름은 무엇인가요? | C12: 1 | E12: 서쪽 ← [ A ] ··· [ 동도 ] → 동쪽 동도와 서도의 방향 관계만 간단히 나타냈어요. | F12: 방향을 단순화한 위치 관계이며 두 섬의 실제 해안선을 그린 지도가 아니에요. | G12: location: 두 큰 섬·부속 도서 / 높이·면적 / 울릉도·오키섬 거리 | H12: 대한민국 외교부 · 독도의 구성 및 위치 https://dokdo.mofa.go.kr/kor/introduce/location.jsp
A13: 920012 | B13: 동쪽 화살표가 왼쪽을 가리키는 위치표에서 동도는 어느 쪽에 놓이나요? | C13: 1 | E13: 동쪽 ← [ A ] ··· [ B ] → 서쪽 동도는 동쪽 섬, 서도는 서쪽 섬이에요. 글자 방향이 아니라 화살표를 따라 읽으세요. | F13: 방향을 단순화한 위치 관계이며 두 섬의 실제 해안선을 그린 지도가 아니에요. | G13: location: 두 큰 섬·부속 도서 / 높이·면적 / 울릉도·오키섬 거리 | H13: 대한민국 외교부 · 독도의 구성 및 위치 https://dokdo.mofa.go.kr/kor/introduce/location.jsp
A14: 920013 | B14: 울릉도에서 독도를 보기 좋은 날씨는 무엇인가요? | C14: 0 | G14: sejong: 우산·무릉과 맑은 날의 가시성; 괄호 안 현대 지명은 외교부 해석 location: 두 큰 섬·부속 도서 / 높이·면적 / 울릉도·오키섬 거리 | H14: 대한민국 외교부 자료실 · 세종실록 지리지(1454) https://dokdo.mofa.go.kr/kor/pds/part06_view02.jsp 대한민국 외교부 · 독도의 구성 및 위치 https://dokdo.mofa.go.kr/kor/introduce/location.jsp
A15: 920014 | B15: 울릉도에서 먼 독도를 보려면 어떤 대기 조건이 필요한가요? | C15: 0 | G15: sejong: 우산·무릉과 맑은 날의 가시성; 괄호 안 현대 지명은 외교부 해석 location: 두 큰 섬·부속 도서 / 높이·면적 / 울릉도·오키섬 거리 | H15: 대한민국 외교부 자료실 · 세종실록 지리지(1454) https://dokdo.mofa.go.kr/kor/pds/part06_view02.jsp 대한민국 외교부 · 독도의 구성 및 위치 https://dokdo.mofa.go.kr/kor/introduce/location.jsp
A16: 920015 | B16: 세종실록 지리지는 두 섬이 보이는 날씨를 어떻게 설명하나요? | C16: 1 | E16: 1454년 『세종실록』 지리지의 역문 요약: 우산과 무릉 두 섬은 멀리 떨어져 있지 않아 날씨가 맑으면 바라볼 수 있다. 우산·무릉은 아래 출처의 해설에서 독도·울릉도로 풀이해요. | G16: sejong: 우산·무릉과 맑은 날의 가시성; 괄호 안 현대 지명은 외교부 해석 location: 두 큰 섬·부속 도서 / 높이·면적 / 울릉도·오키섬 거리 | H16: 대한민국 외교부 자료실 · 세종실록 지리지(1454) https://dokdo.mofa.go.kr/kor/pds/part06_view02.jsp 대한민국 외교부 · 독도의 구성 및 위치 https://dokdo.mofa.go.kr/kor/introduce/location.jsp
A17: 920016 | B17: 두 관찰일 중 울릉도에서 독도를 보기 더 좋은 날은 언제인가요? | C17: 1 | E17: 관찰 계획을 위한 예시: A일은 안개 없이 시야가 맑다. B일은 짙은 안개로 먼 바다가 보이지 않는다. 같은 울릉도 관찰 지점에서 볼 예정이다. | G17: sejong: 우산·무릉과 맑은 날의 가시성; 괄호 안 현대 지명은 외교부 해석 location: 두 큰 섬·부속 도서 / 높이·면적 / 울릉도·오키섬 거리 | H17: 대한민국 외교부 자료실 · 세종실록 지리지(1454) https://dokdo.mofa.go.kr/kor/pds/part06_view02.jsp 대한민국 외교부 · 독도의 구성 및 위치 https://dokdo.mofa.go.kr/kor/introduce/location.jsp
A18: 920017 | B18: 독도의 부속 도서 89개를 셀 때 따로 구분하는 두 큰 섬은 무엇인가요? | C18: 0 | G18: location: 두 큰 섬·부속 도서 / 높이·면적 / 울릉도·오키섬 거리 size: 동도 73,297㎡ / 서도 88,740㎡ / 부속 도서 25,517㎡ / 전체 187,554㎡ | H18: 대한민국 외교부 · 독도의 구성 및 위치 https://dokdo.mofa.go.kr/kor/introduce/location.jsp 대한민국 한국해양과학기술원 · 독도 위치 및 규모 https://www.dokdo.re.kr/home/cms/cmsCont.do?cntnts_sn=64
A19: 920018 | B19: 동도·서도와 부속 도서 89개를 합하면 몇 개인가요? | C19: 0 | G19: location: 두 큰 섬·부속 도서 / 높이·면적 / 울릉도·오키섬 거리 size: 동도 73,297㎡ / 서도 88,740㎡ / 부속 도서 25,517㎡ / 전체 187,554㎡ | H19: 대한민국 외교부 · 독도의 구성 및 위치 https://dokdo.mofa.go.kr/kor/introduce/location.jsp 대한민국 한국해양과학기술원 · 독도 위치 및 규모 https://www.dokdo.re.kr/home/cms/cmsCont.do?cntnts_sn=64
A20: 920019 | B20: 면적표에서 부속 도서 전체의 넓이는 얼마인가요? | C20: 1 | E20: 동도 73,297㎡ 서도 88,740㎡ 부속 도서 89개 25,517㎡ 합계 187,554㎡ | G20: location: 두 큰 섬·부속 도서 / 높이·면적 / 울릉도·오키섬 거리 size: 동도 73,297㎡ / 서도 88,740㎡ / 부속 도서 25,517㎡ / 전체 187,554㎡ | H20: 대한민국 외교부 · 독도의 구성 및 위치 https://dokdo.mofa.go.kr/kor/introduce/location.jsp 대한민국 한국해양과학기술원 · 독도 위치 및 규모 https://www.dokdo.re.kr/home/cms/cmsCont.do?cntnts_sn=64
A21: 920020 | B21: 독도 전체 면적을 동도와 서도 면적만 더해 계산하면 무엇이 빠지나요? | C21: 1 | E21: 독도 전체 땅 면적 187,554㎡ / 동도 73,297㎡ / 서도 88,740㎡. 부속 도서도 독도를 이루는 땅이에요. | G21: location: 두 큰 섬·부속 도서 / 높이·면적 / 울릉도·오키섬 거리 size: 동도 73,297㎡ / 서도 88,740㎡ / 부속 도서 25,517㎡ / 전체 187,554㎡ | H21: 대한민국 외교부 · 독도의 구성 및 위치 https://dokdo.mofa.go.kr/kor/introduce/location.jsp 대한민국 한국해양과학기술원 · 독도 위치 및 규모 https://www.dokdo.re.kr/home/cms/cmsCont.do?cntnts_sn=64
A22: 920021 | B22: 독도의 두 큰 섬 중 더 높은 섬은 무엇인가요? | C22: 0 | G22: location: 두 큰 섬·부속 도서 / 높이·면적 / 울릉도·오키섬 거리 size: 동도 73,297㎡ / 서도 88,740㎡ / 부속 도서 25,517㎡ / 전체 187,554㎡ | H22: 대한민국 외교부 · 독도의 구성 및 위치 https://dokdo.mofa.go.kr/kor/introduce/location.jsp 대한민국 한국해양과학기술원 · 독도 위치 및 규모 https://www.dokdo.re.kr/home/cms/cmsCont.do?cntnts_sn=64
A23: 920022 | B23: 독도에서 최고 높이가 98.6m인 큰 섬은 무엇인가요? | C23: 0 | G23: location: 두 큰 섬·부속 도서 / 높이·면적 / 울릉도·오키섬 거리 size: 동도 73,297㎡ / 서도 88,740㎡ / 부속 도서 25,517㎡ / 전체 187,554㎡ | H23: 대한민국 외교부 · 독도의 구성 및 위치 https://dokdo.mofa.go.kr/kor/introduce/location.jsp 대한민국 한국해양과학기술원 · 독도 위치 및 규모 https://www.dokdo.re.kr/home/cms/cmsCont.do?cntnts_sn=64
A24: 920023 | B24: 높이표에 따르면 서도는 동도보다 몇 m 더 높은가요? | C24: 1 | E24: 서도 최고 높이 168.5m 동도 최고 높이 98.6m 두 값은 해수면을 기준으로 한 높이예요. | G24: location: 두 큰 섬·부속 도서 / 높이·면적 / 울릉도·오키섬 거리 size: 동도 73,297㎡ / 서도 88,740㎡ / 부속 도서 25,517㎡ / 전체 187,554㎡ | H24: 대한민국 외교부 · 독도의 구성 및 위치 https://dokdo.mofa.go.kr/kor/introduce/location.jsp 대한민국 한국해양과학기술원 · 독도 위치 및 규모 https://www.dokdo.re.kr/home/cms/cmsCont.do?cntnts_sn=64
A25: 920024 | B25: 표의 높이를 기준으로 100m보다 높은 곳이 있는 섬은 어디인가요? | C25: 1 | E25: 서도 168.5m / 동도 98.6m. 지형도의 100m 높이선을 넣을 수 있는 섬을 판단하려고 해요. | G25: location: 두 큰 섬·부속 도서 / 높이·면적 / 울릉도·오키섬 거리 size: 동도 73,297㎡ / 서도 88,740㎡ / 부속 도서 25,517㎡ / 전체 187,554㎡ | H25: 대한민국 외교부 · 독도의 구성 및 위치 https://dokdo.mofa.go.kr/kor/introduce/location.jsp 대한민국 한국해양과학기술원 · 독도 위치 및 규모 https://www.dokdo.re.kr/home/cms/cmsCont.do?cntnts_sn=64
A26: 920025 | B26: 독도의 두 큰 섬 중 땅의 넓이가 더 넓은 섬은 무엇인가요? | C26: 0 | G26: location: 두 큰 섬·부속 도서 / 높이·면적 / 울릉도·오키섬 거리 size: 동도 73,297㎡ / 서도 88,740㎡ / 부속 도서 25,517㎡ / 전체 187,554㎡ | H26: 대한민국 외교부 · 독도의 구성 및 위치 https://dokdo.mofa.go.kr/kor/introduce/location.jsp 대한민국 한국해양과학기술원 · 독도 위치 및 규모 https://www.dokdo.re.kr/home/cms/cmsCont.do?cntnts_sn=64
A27: 920026 | B27: 독도 면적표의 ㎡는 무엇을 나타내는 단위인가요? | C27: 1 | E27: 서도: 88,740㎡ / 동도: 73,297㎡ | G27: location: 두 큰 섬·부속 도서 / 높이·면적 / 울릉도·오키섬 거리 size: 동도 73,297㎡ / 서도 88,740㎡ / 부속 도서 25,517㎡ / 전체 187,554㎡ | H27: 대한민국 외교부 · 독도의 구성 및 위치 https://dokdo.mofa.go.kr/kor/introduce/location.jsp 대한민국 한국해양과학기술원 · 독도 위치 및 규모 https://www.dokdo.re.kr/home/cms/cmsCont.do?cntnts_sn=64
A28: 920027 | B28: 표에서 해안선의 둘레가 더 긴 큰 섬은 어디인가요? | C28: 1 | E28: 동도: 면적 73,297㎡, 둘레 2.8km 서도: 면적 88,740㎡, 둘레 2.6km | G28: location: 두 큰 섬·부속 도서 / 높이·면적 / 울릉도·오키섬 거리 size: 동도 73,297㎡ / 서도 88,740㎡ / 부속 도서 25,517㎡ / 전체 187,554㎡ | H28: 대한민국 외교부 · 독도의 구성 및 위치 https://dokdo.mofa.go.kr/kor/introduce/location.jsp 대한민국 한국해양과학기술원 · 독도 위치 및 규모 https://www.dokdo.re.kr/home/cms/cmsCont.do?cntnts_sn=64
A29: 920028 | B29: 표에 맞게 서도와 동도의 면적·둘레를 함께 비교한 것은 무엇인가요? | C29: 1 | E29: 동도 73,297㎡ / 둘레 2.8km 서도 88,740㎡ / 둘레 2.6km 면적은 땅의 넓이, 둘레는 해안선을 따라 잰 길이예요. | G29: location: 두 큰 섬·부속 도서 / 높이·면적 / 울릉도·오키섬 거리 size: 동도 73,297㎡ / 서도 88,740㎡ / 부속 도서 25,517㎡ / 전체 187,554㎡ | H29: 대한민국 외교부 · 독도의 구성 및 위치 https://dokdo.mofa.go.kr/kor/introduce/location.jsp 대한민국 한국해양과학기술원 · 독도 위치 및 규모 https://www.dokdo.re.kr/home/cms/cmsCont.do?cntnts_sn=64
A30: 920029 | B30: 동도와 서도는 무엇을 사이에 두고 떨어져 있나요? | C30: 0 | F30: 해안 사이의 간격이지 두 정상 사이 거리나 걷는 길의 길이가 아니에요. | G30: geology: 해저 화산의 형성 / 해안 침식 지형 / 물골 / 지형 변화 reserve: 해안지형·조류 번식지·식생 보호; 지정 날짜를 묻는 문항은 제외 | H30: 대한민국 한국해양과학기술원 · 독도 지형 및 지질 https://www.dokdo.re.kr/home/cms/cmsCont.do?cntnts_sn=66 대한민국 국가유산청 · 독도 천연보호구역 https://www.heritage.go.kr/heri/cul/culSelectDetail.do?VdkVgwKey=16%2C03360000%2C37&pageNo=1_1_2_0
A31: 920030 | B31: 동도와 서도의 가장 가까운 해안 사이 거리는 약 얼마인가요? | C31: 0 | F31: 해안 사이의 간격이지 두 정상 사이 거리나 걷는 길의 길이가 아니에요. | G31: geology: 해저 화산의 형성 / 해안 침식 지형 / 물골 / 지형 변화 reserve: 해안지형·조류 번식지·식생 보호; 지정 날짜를 묻는 문항은 제외 | H31: 대한민국 한국해양과학기술원 · 독도 지형 및 지질 https://www.dokdo.re.kr/home/cms/cmsCont.do?cntnts_sn=66 대한민국 국가유산청 · 독도 천연보호구역 https://www.heritage.go.kr/heri/cul/culSelectDetail.do?VdkVgwKey=16%2C03360000%2C37&pageNo=1_1_2_0
A32: 920031 | B32: 151m라는 간격을 지도에 표시할 때 양 끝은 어디에 두어야 하나요? | C32: 1 | E32: 거리 설명: 동도와 서도가 가장 가까이 마주한 해안 사이의 간격은 약 151m이다. | F32: 해안 사이의 간격이지 두 정상 사이 거리나 걷는 길의 길이가 아니에요. | G32: geology: 해저 화산의 형성 / 해안 침식 지형 / 물골 / 지형 변화 reserve: 해안지형·조류 번식지·식생 보호; 지정 날짜를 묻는 문항은 제외 | H32: 대한민국 한국해양과학기술원 · 독도 지형 및 지질 https://www.dokdo.re.kr/home/cms/cmsCont.do?cntnts_sn=66 대한민국 국가유산청 · 독도 천연보호구역 https://www.heritage.go.kr/heri/cul/culSelectDetail.do?VdkVgwKey=16%2C03360000%2C37&pageNo=1_1_2_0
A33: 920032 | B33: 축척이 1cm당 50m인 지도에서 151m 간격은 약 몇 cm인가요? | C33: 1 | E33: 실제 해안 간격: 약 151m 학습용 지도 축척: 1cm가 실제 50m를 나타냄 이 축척은 계산 연습을 위해 정한 값이에요. | F33: 해안 사이의 간격이지 두 정상 사이 거리나 걷는 길의 길이가 아니에요. | G33: geology: 해저 화산의 형성 / 해안 침식 지형 / 물골 / 지형 변화 reserve: 해안지형·조류 번식지·식생 보호; 지정 날짜를 묻는 문항은 제외 | H33: 대한민국 한국해양과학기술원 · 독도 지형 및 지질 https://www.dokdo.re.kr/home/cms/cmsCont.do?cntnts_sn=66 대한민국 국가유산청 · 독도 천연보호구역 https://www.heritage.go.kr/heri/cul/culSelectDetail.do?VdkVgwKey=16%2C03360000%2C37&pageNo=1_1_2_0
A34: 920033 | B34: 독도에서 가파른 봉우리가 두드러지는 큰 섬은 무엇인가요? | C34: 0 | G34: reserve: 해안지형·조류 번식지·식생 보호; 지정 날짜를 묻는 문항은 제외 photos: 두 섬·선착장·등대로 가는 길·바위의 사진 설명; 사진 파일은 재배포하지 않음 | H34: 대한민국 국가유산청 · 독도 천연보호구역 https://www.heritage.go.kr/heri/cul/culSelectDetail.do?VdkVgwKey=16%2C03360000%2C37&pageNo=1_1_2_0 대한민국 전북교육청 · 독도 사진 자료 https://www.jbe.go.kr/dokdo/assets/sub/picture.html
A35: 920034 | B35: 독도의 헬기장 등 시설이 자리한 비교적 평탄한 상부는 어느 섬에 있나요? | C35: 0 | G35: reserve: 해안지형·조류 번식지·식생 보호; 지정 날짜를 묻는 문항은 제외 photos: 두 섬·선착장·등대로 가는 길·바위의 사진 설명; 사진 파일은 재배포하지 않음 | H35: 대한민국 국가유산청 · 독도 천연보호구역 https://www.heritage.go.kr/heri/cul/culSelectDetail.do?VdkVgwKey=16%2C03360000%2C37&pageNo=1_1_2_0 대한민국 전북교육청 · 독도 사진 자료 https://www.jbe.go.kr/dokdo/assets/sub/picture.html
A36: 920035 | B36: 지형 설명 A는 동도와 서도 중 어느 섬인가요? | C36: 1 | E36: A: 해안에는 절벽이 있고, 정상 부근은 비교적 평탄하여 헬기장과 시설이 있다. B: 높고 가파른 봉우리가 두드러진다. | G36: reserve: 해안지형·조류 번식지·식생 보호; 지정 날짜를 묻는 문항은 제외 photos: 두 섬·선착장·등대로 가는 길·바위의 사진 설명; 사진 파일은 재배포하지 않음 | H36: 대한민국 국가유산청 · 독도 천연보호구역 https://www.heritage.go.kr/heri/cul/culSelectDetail.do?VdkVgwKey=16%2C03360000%2C37&pageNo=1_1_2_0 대한민국 전북교육청 · 독도 사진 자료 https://www.jbe.go.kr/dokdo/assets/sub/picture.html
A37: 920036 | B37: 독도 모형에서 동도를 서도와 똑같은 뾰족한 산으로 만들었다면 무엇을 고쳐야 하나요? | C37: 1 | E37: 지형 자료: 서도 168.5m, 가파른 봉우리 / 동도 98.6m, 해안 절벽과 비교적 평탄한 정상 부근. 수정할 모형: 두 섬을 높이만 다른 똑같은 뾰족한 산으로 만듦. | G37: reserve: 해안지형·조류 번식지·식생 보호; 지정 날짜를 묻는 문항은 제외 photos: 두 섬·선착장·등대로 가는 길·바위의 사진 설명; 사진 파일은 재배포하지 않음 | H37: 대한민국 국가유산청 · 독도 천연보호구역 https://www.heritage.go.kr/heri/cul/culSelectDetail.do?VdkVgwKey=16%2C03360000%2C37&pageNo=1_1_2_0 대한민국 전북교육청 · 독도 사진 자료 https://www.jbe.go.kr/dokdo/assets/sub/picture.html
A38: 920037 | B38: 동도와 서도 아래 바닷속에도 독도의 지형이 이어지나요? | C38: 0 | G38: geology: 해저 화산의 형성 / 해안 침식 지형 / 물골 / 지형 변화 | H38: 대한민국 한국해양과학기술원 · 독도 지형 및 지질 https://www.dokdo.re.kr/home/cms/cmsCont.do?cntnts_sn=66
A39: 920038 | B39: 독도의 두 큰 섬은 무엇의 일부가 바다 위로 드러난 것인가요? | C39: 0 | G39: geology: 해저 화산의 형성 / 해안 침식 지형 / 물골 / 지형 변화 | H39: 대한민국 한국해양과학기술원 · 독도 지형 및 지질 https://www.dokdo.re.kr/home/cms/cmsCont.do?cntnts_sn=66
A40: 920039 | B40: 독도 설명의 약 2,300m는 어디서부터 잰 규모인가요? | C40: 1 | E40: 서도의 해발 높이: 168.5m. 독도 화산체의 전체 높이: 해저 기저부부터 약 2,300m. 높이를 비교할 때 출발 기준을 확인하세요. | G40: geology: 해저 화산의 형성 / 해안 침식 지형 / 물골 / 지형 변화 | H40: 대한민국 한국해양과학기술원 · 독도 지형 및 지질 https://www.dokdo.re.kr/home/cms/cmsCont.do?cntnts_sn=66
...

Sheet 영어240
A1: ID | B1: Question | C1: A | D1: B | E1: C | F1: D | G1: Answer | H1: Why correct | I1: Takeaway | J1: Material / context | K1: Source
A2: 920001 | B2: What are the names of Dokdo’s two main islands? | C2: Dongdo and Seodo | D2: Ulleungdo and Dongdo | E2: Jejudo and Seodo | F2: Ulleungdo and Jejudo | G2: 1 | H2: Dongdo and Seodo are the two main islands, surrounded by smaller islets. | I2: Dokdo consists of Dongdo, Seodo and the smaller islets around them. | K2: 대한민국 외교부 · 독도의 구성 및 위치 https://dokdo.mofa.go.kr/kor/introduce/location.jsp
A3: 920002 | B3: What other land surrounds Dokdo’s two main islands? | C3: Smaller rocky islets | D3: The main island of Ulleungdo | E3: Japan’s Oki Islands | G3: 1 | H3: Dokdo includes the surrounding rocky islets as well as Dongdo and Seodo. | I3: Dokdo consists of Dongdo, Seodo and the smaller islets around them. | K3: 대한민국 외교부 · 독도의 구성 및 위치 https://dokdo.mofa.go.kr/kor/introduce/location.jsp
A4: 920003 | B4: What land should be added to a Dokdo sign that shows only its two main islands? | C4: All of Ulleungdo | D4: The surrounding associated islets | E4: All of Japan’s Oki Islands | G4: 2 | H4: The description includes the associated islets as well as the two main islands. | I4: Dokdo consists of Dongdo, Seodo and the smaller islets around them. | J4: Dokdo’s composition: Dongdo + Seodo + 89 associated islets. These are smaller islands around the two main islands. | K4: 대한민국 외교부 · 독도의 구성 및 위치 https://dokdo.mofa.go.kr/kor/introduce/location.jsp
A5: 920004 | B5: How should the statement “Dokdo is the name of Dongdo alone” be corrected? | C5: It names Dongdo and Ulleungdo | D5: It names Seodo alone | E5: It names Dongdo, Seodo and the surrounding islets | G5: 3 | H5: Dongdo is only part of Dokdo, which also includes Seodo and associated islets. | I5: Dokdo consists of Dongdo, Seodo and the smaller islets around them. | J5: The composition data includes Dongdo, Seodo and 89 associated islets within Dokdo. | K5: 대한민국 외교부 · 독도의 구성 및 위치 https://dokdo.mofa.go.kr/kor/introduce/location.jsp
A6: 920005 | B6: In which direction from Ulleungdo is Dokdo? | C6: Northeast | D6: Southeast | E6: Southwest | F6: Northwest | G6: 2 | H6: Dokdo is both east and south of Ulleungdo: southeast. | I6: Dokdo lies about 87.4 km southeast of Ulleungdo. | K6: 대한민국 해양수산부 · 독도의 주소와 위치 https://www.mof.go.kr/doc/ko/selectDoc.do?bbsSeq=27&docSeq=20937&menuSeq=929 대한민국 외교부 · 독도의 구성 및 위치 https://dokdo.mofa.go.kr/kor/introduce/location.jsp
A7: 920006 | B7: Approximately how far apart are Ulleungdo and Dokdo? | C7: 157.5 km | D7: 8.74 km | E7: 87.4 km | F7: 874 km | G7: 3 | H7: The distance between Ulleungdo and Dokdo is about 87.4 km. | I7: Dokdo lies about 87.4 km southeast of Ulleungdo. | K7: 대한민국 해양수산부 · 독도의 주소와 위치 https://www.mof.go.kr/doc/ko/selectDoc.do?bbsSeq=27&docSeq=20937&menuSeq=929 대한민국 외교부 · 독도의 구성 및 위치 https://dokdo.mofa.go.kr/kor/introduce/location.jsp
A8: 920007 | B8: Which place is nearer to Dokdo in the distance table? | C8: Ulleungdo | D8: Japan’s Oki Islands | G8: 1 | H8: 87.4 km is less than 157.5 km, so Ulleungdo is nearer. | I8: Dokdo lies about 87.4 km southeast of Ulleungdo. | J8: Dokdo to Ulleungdo: 87.4 km Dokdo to Japan’s Oki Islands: 157.5 km | K8: 대한민국 해양수산부 · 독도의 주소와 위치 https://www.mof.go.kr/doc/ko/selectDoc.do?bbsSeq=27&docSeq=20937&menuSeq=929 대한민국 외교부 · 독도의 구성 및 위치 https://dokdo.mofa.go.kr/kor/introduce/location.jsp
A9: 920008 | B9: How many kilometres nearer to Dokdo is Ulleungdo than the Oki Islands? | C9: 244.9 km | D9: 87.4 km | E9: 157.5 km | F9: 70.1 km | G9: 4 | H9: Subtracting gives 157.5 − 87.4 = 70.1 km, the difference in distance. | I9: Dokdo lies about 87.4 km southeast of Ulleungdo. | J9: Dokdo–Ulleungdo: 87.4 km. Dokdo–Japan’s Oki Islands: 157.5 km. Use these distances to calculate the difference. | K9: 대한민국 해양수산부 · 독도의 주소와 위치 https://www.mof.go.kr/doc/ko/selectDoc.do?bbsSeq=27&docSeq=20937&menuSeq=929 대한민국 외교부 · 독도의 구성 및 위치 https://dokdo.mofa.go.kr/kor/introduce/location.jsp
A10: 920009 | B10: Which main island is on Dokdo’s eastern side? | C10: Seodo | D10: Dongdo | G10: 2 | H10: “Dong” means east; Dongdo is the eastern main island. | I10: Dongdo is the eastern main island and Seodo is the western one. | J10: This simplifies their directional relationship; it is not a coastline map. | K10: 대한민국 외교부 · 독도의 구성 및 위치 https://dokdo.mofa.go.kr/kor/introduce/location.jsp
A11: 920010 | B11: What name labels Dokdo’s western main island? | C11: Seodo | D11: Dongdo | G11: 1 | H11: Seodo is the western island; Dongdo is the eastern one. | I11: Dongdo is the eastern main island and Seodo is the western one. | J11: This simplifies their directional relationship; it is not a coastline map. | K11: 대한민국 외교부 · 독도의 구성 및 위치 https://dokdo.mofa.go.kr/kor/introduce/location.jsp
A12: 920011 | B12: Which island name belongs at A in the position key? | C12: Dongdo | D12: Seodo | G12: 2 | H12: A occupies the western position, so it is Seodo. | I12: Dongdo is the eastern main island and Seodo is the western one. | J12: West ← [ A ] ··· [ Dongdo ] → East This key shows only the simplified east–west relationship. This simplifies their directional relationship; it is not a coastline map. | K12: 대한민국 외교부 · 독도의 구성 및 위치 https://dokdo.mofa.go.kr/kor/introduce/location.jsp
A13: 920012 | B13: On a position key with east pointing left, on which side is Dongdo placed? | C13: Left | D13: Right | G13: 1 | H13: East points left in this key, so the eastern island, Dongdo, is on the left. | I13: Dongdo is the eastern main island and Seodo is the western one. | J13: East ← [ A ] ··· [ B ] → West Dongdo is the eastern island and Seodo is the western island. Follow the arrows in this key. This simplifies their directional relationship; it is not a coastline map. | K13: 대한민국 외교부 · 독도의 구성 및 위치 https://dokdo.mofa.go.kr/kor/introduce/location.jsp
A14: 920013 | B14: What weather offers a good chance of seeing Dokdo from Ulleungdo? | C14: Clear weather with good visibility | D14: Dense fog | E14: Rain that obscures the view | G14: 1 | H14: Clear air allows a distant island such as Dokdo to be visible. | I14: Dokdo can be seen from Ulleungdo in clear weather with good visibility. | K14: 대한민국 외교부 자료실 · 세종실록 지리지(1454) https://dokdo.mofa.go.kr/kor/pds/part06_view02.jsp 대한민국 외교부 · 독도의 구성 및 위치 https://dokdo.mofa.go.kr/kor/introduce/location.jsp
A15: 920014 | B15: Which atmospheric condition helps observers see distant Dokdo from Ulleungdo? | C15: Dense fog over the sea | D15: Little fog and clear visibility | E15: Heavy rain reducing visibility | G15: 2 | H15: Distant viewing requires conditions with little obscuring fog. | I15: Dokdo can be seen from Ulleungdo in clear weather with good visibility. | K15: 대한민국 외교부 자료실 · 세종실록 지리지(1454) https://dokdo.mofa.go.kr/kor/pds/part06_view02.jsp 대한민국 외교부 · 독도의 구성 및 위치 https://dokdo.mofa.go.kr/kor/introduce/location.jsp
A16: 920015 | B16: What weather does the Sejong geographical record associate with seeing the two islands? | C16: When there is dense fog | D16: Every day regardless of conditions | E16: When the weather is clear | G16: 3 | H16: The translation says the islands can be seen when the weather is clear. | I16: Dokdo can be seen from Ulleungdo in clear weather with good visibility. | J16: Summary of the translated 1454 Sejong geographical record: Usan and Mureung are not far apart and can be seen in clear weather. The cited commentary identifies them as Dokdo and Ulleungdo. | K16: 대한민국 외교부 자료실 · 세종실록 지리지(1454) https://dokdo.mofa.go.kr/kor/pds/part06_view02.jsp 대한민국 외교부 · 독도의 구성 및 위치 https://dokdo.mofa.go.kr/kor/introduce/location.jsp
A17: 920016 | B17: Which of the two days is more suitable for viewing Dokdo from Ulleungdo? | C17: Day B | D17: Day A | G17: 2 | H17: Day A has clearer visibility for viewing the distant islands. | I17: Dokdo can be seen from Ulleungdo in clear weather with good visibility. | J17: Illustrative plan: day A has clear visibility without fog; on day B dense fog obscures the distant sea. Both observations would use the same point on Ulleungdo. | K17: 대한민국 외교부 자료실 · 세종실록 지리지(1454) https://dokdo.mofa.go.kr/kor/pds/part06_view02.jsp 대한민국 외교부 · 독도의 구성 및 위치 https://dokdo.mofa.go.kr/kor/introduce/location.jsp
A18: 920017 | B18: Which two main islands are counted separately from Dokdo’s 89 associated islets? | C18: Dongdo and Seodo | D18: Ulleungdo and Dokdo | E18: Dongdo and Ulleungdo | G18: 1 | H18: The 89 associated islets are in addition to Dongdo and Seodo. | I18: Dokdo’s 89 associated islets are counted separately from Dongdo and Seodo. | K18: 대한민국 외교부 · 독도의 구성 및 위치 https://dokdo.mofa.go.kr/kor/introduce/location.jsp 대한민국 한국해양과학기술원 · 독도 위치 및 규모 https://www.dokdo.re.kr/home/cms/cmsCont.do?cntnts_sn=64
A19: 920018 | B19: How many islands are there when Dongdo, Seodo and 89 associated islets are counted together? | C19: 91 | D19: 89 | E19: 90 | F19: 93 | G19: 1 | H19: Two main islands plus 89 associated islets equals 91. | I19: Dokdo’s 89 associated islets are counted separately from Dongdo and Seodo. | K19: 대한민국 외교부 · 독도의 구성 및 위치 https://dokdo.mofa.go.kr/kor/introduce/location.jsp 대한민국 한국해양과학기술원 · 독도 위치 및 규모 https://www.dokdo.re.kr/home/cms/cmsCont.do?cntnts_sn=64
A20: 920019 | B20: What is the combined area of the associated islets in the table? | C20: 73,297 m² | D20: 25,517 m² | E20: 88,740 m² | F20: 187,554 m² | G20: 2 | H20: The associated-islets row is 25,517 m², not the total or a main island’s area. | I20: Dokdo’s 89 associated islets are counted separately from Dongdo and Seodo. | J20: Dongdo: 73,297 m² Seodo: 88,740 m² 89 associated islets: 25,517 m² Total: 187,554 m² | K20: 대한민국 외교부 · 독도의 구성 및 위치 https://dokdo.mofa.go.kr/kor/introduce/location.jsp 대한민국 한국해양과학기술원 · 독도 위치 및 규모 https://www.dokdo.re.kr/home/cms/cmsCont.do?cntnts_sn=64
A21: 920020 | B21: What is left out when Dokdo’s total area is calculated using only Dongdo and Seodo? | C21: 25,517 m² of sea between the islands | D21: 25,517 m² of associated islets | E21: 25,517 m² of Ulleungdo | G21: 2 | H21: 187,554 − 73,297 − 88,740 = 25,517 m², the land area of the associated islets. | I21: Dokdo’s 89 associated islets are counted separately from Dongdo and Seodo. | J21: Dokdo total land area: 187,554 m²; Dongdo: 73,297 m²; Seodo: 88,740 m². Associated islets also contribute land area. | K21: 대한민국 외교부 · 독도의 구성 및 위치 https://dokdo.mofa.go.kr/kor/introduce/location.jsp 대한민국 한국해양과학기술원 · 독도 위치 및 규모 https://www.dokdo.re.kr/home/cms/cmsCont.do?cntnts_sn=64
A22: 920021 | B22: Which of Dokdo’s two main islands is higher? | C22: Seodo | D22: Dongdo | G22: 1 | H22: Seodo reaches 168.5 m, higher than Dongdo’s 98.6 m. | I22: Seodo is the higher main island: 168.5 m, compared with Dongdo’s 98.6 m. | K22: 대한민국 외교부 · 독도의 구성 및 위치 https://dokdo.mofa.go.kr/kor/introduce/location.jsp 대한민국 한국해양과학기술원 · 독도 위치 및 규모 https://www.dokdo.re.kr/home/cms/cmsCont.do?cntnts_sn=64
A23: 920022 | B23: Which main island of Dokdo reaches a maximum height of 98.6 m? | C23: Seodo | D23: Dongdo | G23: 2 | H23: 98.6 m is Dongdo’s maximum elevation. | I23: Seodo is the higher main island: 168.5 m, compared with Dongdo’s 98.6 m. | K23: 대한민국 외교부 · 독도의 구성 및 위치 https://dokdo.mofa.go.kr/kor/introduce/location.jsp 대한민국 한국해양과학기술원 · 독도 위치 및 규모 https://www.dokdo.re.kr/home/cms/cmsCont.do?cntnts_sn=64
A24: 920023 | B24: According to the height table, how many metres higher is Seodo than Dongdo? | C24: 267.1 m | D24: 98.6 m | E24: 69.9 m | F24: 151 m | G24: 3 | H24: Subtracting the two elevations gives 168.5 − 98.6 = 69.9 m. | I24: Seodo is the higher main island: 168.5 m, compared with Dongdo’s 98.6 m. | J24: Seodo maximum elevation: 168.5 m Dongdo maximum elevation: 98.6 m Both elevations are measured relative to sea level. | K24: 대한민국 외교부 · 독도의 구성 및 위치 https://dokdo.mofa.go.kr/kor/introduce/location.jsp 대한민국 한국해양과학기술원 · 독도 위치 및 규모 https://www.dokdo.re.kr/home/cms/cmsCont.do?cntnts_sn=64
A25: 920024 | B25: Which island has land above 100 m, based on the elevations in the table? | C25: Dongdo only | D25: Both islands | E25: Neither island | F25: Seodo only | G25: 4 | H25: Seodo reaches 168.5 m; Dongdo peaks at 98.6 m and therefore has no point at 100 m. | I25: Seodo is the higher main island: 168.5 m, compared with Dongdo’s 98.6 m. | J25: Seodo: 168.5 m; Dongdo: 98.6 m. Consider which island could have a 100 m contour. | K25: 대한민국 외교부 · 독도의 구성 및 위치 https://dokdo.mofa.go.kr/kor/introduce/location.jsp 대한민국 한국해양과학기술원 · 독도 위치 및 규모 https://www.dokdo.re.kr/home/cms/cmsCont.do?cntnts_sn=64
A26: 920025 | B26: Which of Dokdo’s main islands has the larger land area? | C26: Seodo | D26: Dongdo | G26: 1 | H26: Seodo’s 88,740 m² exceeds Dongdo’s 73,297 m². | I26: Seodo has the larger area, but Dongdo has the longer coastline. | K26: 대한민국 외교부 · 독도의 구성 및 위치 https://dokdo.mofa.go.kr/kor/introduce/location.jsp 대한민국 한국해양과학기술원 · 독도 위치 및 규모 https://www.dokdo.re.kr/home/cms/cmsCont.do?cntnts_sn=64
A27: 920026 | B27: What does m² measure in Dokdo’s area table? | C27: Peak elevation | D27: Length along the coastline | E27: Land area | G27: 3 | H27: Square metres measure area, unlike metres used for elevation. | I27: Seodo has the larger area, but Dongdo has the longer coastline. | J27: Seodo: 88,740 m² / Dongdo: 73,297 m² | K27: 대한민국 외교부 · 독도의 구성 및 위치 https://dokdo.mofa.go.kr/kor/introduce/location.jsp 대한민국 한국해양과학기술원 · 독도 위치 및 규모 https://www.dokdo.re.kr/home/cms/cmsCont.do?cntnts_sn=64
A28: 920027 | B28: Which main island has the longer coastline in the table? | C28: Seodo | D28: Dongdo | G28: 2 | H28: Dongdo’s 2.8 km coastline is longer than Seodo’s 2.6 km. | I28: Seodo has the larger area, but Dongdo has the longer coastline. | J28: Dongdo: area 73,297 m²; coastline 2.8 km Seodo: area 88,740 m²; coastline 2.6 km | K28: 대한민국 외교부 · 독도의 구성 및 위치 https://dokdo.mofa.go.kr/kor/introduce/location.jsp 대한민국 한국해양과학기술원 · 독도 위치 및 규모 https://www.dokdo.re.kr/home/cms/cmsCont.do?cntnts_sn=64
A29: 920028 | B29: Which comparison of both area and coastline agrees with the table? | C29: Seodo has more area; Dongdo has a longer coastline | D29: Seodo has more area and therefore a longer coastline | E29: Dongdo has both more area and a longer coastline | G29: 1 | H29: Area and coastline length are distinct quantities; different islands lead in each. | I29: Seodo has the larger area, but Dongdo has the longer coastline. | J29: Dongdo: 73,297 m² / coastline 2.8 km Seodo: 88,740 m² / coastline 2.6 km Area measures land extent; coastline length follows the shore. | K29: 대한민국 외교부 · 독도의 구성 및 위치 https://dokdo.mofa.go.kr/kor/introduce/location.jsp 대한민국 한국해양과학기술원 · 독도 위치 및 규모 https://www.dokdo.re.kr/home/cms/cmsCont.do?cntnts_sn=64
A30: 920029 | B30: What separates Dongdo and Seodo? | C30: A land road | D30: Sea | E30: A river | G30: 2 | H30: Their exposed land areas are separated by seawater. | I30: The nearest shores of Dongdo and Seodo are about 151 m apart. | J30: This is a shore-to-shore gap, not the peak-to-peak distance or a walking route. | K30: 대한민국 한국해양과학기술원 · 독도 지형 및 지질 https://www.dokdo.re.kr/home/cms/cmsCont.do?cntnts_sn=66 대한민국 국가유산청 · 독도 천연보호구역 https://www.heritage.go.kr/heri/cul/culSelectDetail.do?VdkVgwKey=16%2C03360000%2C37&pageNo=1_1_2_0
A31: 920030 | B31: Approximately how far apart are the nearest shores of Dongdo and Seodo? | C31: 151 m | D31: 87.4 km | E31: 98.6 m | F31: 168.5 m | G31: 1 | H31: About 151 m is the gap between the nearest shores of the main islands. | I31: The nearest shores of Dongdo and Seodo are about 151 m apart. | J31: This is a shore-to-shore gap, not the peak-to-peak distance or a walking route. | K31: 대한민국 한국해양과학기술원 · 독도 지형 및 지질 https://www.dokdo.re.kr/home/cms/cmsCont.do?cntnts_sn=66 대한민국 국가유산청 · 독도 천연보호구역 https://www.heritage.go.kr/heri/cul/culSelectDetail.do?VdkVgwKey=16%2C03360000%2C37&pageNo=1_1_2_0
A32: 920031 | B32: Where should the ends of a line marking the 151 m gap be placed? | C32: At the two peaks | D32: At the lighthouse and residence | E32: At the nearest points on the two shores | G32: 3 | H32: The measurement is shore-to-shore, so the line connects those nearest points. | I32: The nearest shores of Dongdo and Seodo are about 151 m apart. | J32: Distance definition: the nearest facing shores of Dongdo and Seodo are approximately 151 m apart. This is a shore-to-shore gap, not the peak-to-peak distance or a walking route. | K32: 대한민국 한국해양과학기술원 · 독도 지형 및 지질 https://www.dokdo.re.kr/home/cms/cmsCont.do?cntnts_sn=66 대한민국 국가유산청 · 독도 천연보호구역 https://www.heritage.go.kr/heri/cul/culSelectDetail.do?VdkVgwKey=16%2C03360000%2C37&pageNo=1_1_2_0
A33: 920032 | B33: On a map where 1 cm represents 50 m, how long is a 151 m gap? | C33: 7,550 cm | D33: 3.02 cm | E33: 151 cm | F33: 0.302 cm | G33: 2 | H33: 151 ÷ 50 = 3.02 cm. | I33: The nearest shores of Dongdo and Seodo are about 151 m apart. | J33: Actual shore gap: about 151 m Practice map scale: 1 cm represents 50 m The scale is chosen for this exercise. This is a shore-to-shore gap, not the peak-to-peak distance or a walking route. | K33: 대한민국 한국해양과학기술원 · 독도 지형 및 지질 https://www.dokdo.re.kr/home/cms/cmsCont.do?cntnts_sn=66 대한민국 국가유산청 · 독도 천연보호구역 https://www.heritage.go.kr/heri/cul/culSelectDetail.do?VdkVgwKey=16%2C03360000%2C37&pageNo=1_1_2_0
A34: 920033 | B34: Which main island of Dokdo is especially marked by a steep peak? | C34: Seodo | D34: Dongdo | G34: 1 | H34: Seodo is characterised by its higher, steeply rising peak. | I34: Seodo rises steeply; Dongdo has a comparatively level upper area. | K34: 대한민국 국가유산청 · 독도 천연보호구역 https://www.heritage.go.kr/heri/cul/culSelectDetail.do?VdkVgwKey=16%2C03360000%2C37&pageNo=1_1_2_0 대한민국 전북교육청 · 독도 사진 자료 https://www.jbe.go.kr/dokdo/assets/sub/picture.html
A35: 920034 | B35: Which island has the comparatively level upper area used by facilities such as the helipad? | C35: Seodo | D35: Dongdo | G35: 2 | H35: Dongdo’s relatively level upper area accommodates the helipad and other facilities. | I35: Seodo rises steeply; Dongdo has a comparatively level upper area. | K35: 대한민국 국가유산청 · 독도 천연보호구역 https://www.heritage.go.kr/heri/cul/culSelectDetail.do?VdkVgwKey=16%2C03360000%2C37&pageNo=1_1_2_0 대한민국 전북교육청 · 독도 사진 자료 https://www.jbe.go.kr/dokdo/assets/sub/picture.html
A36: 920035 | B36: Does terrain description A refer to Dongdo or Seodo? | C36: Dongdo | D36: Seodo | G36: 1 | H36: A describes the relatively level upper area with facilities on Dongdo. | I36: Seodo rises steeply; Dongdo has a comparatively level upper area. | J36: A: coastal cliffs, with a comparatively level upper area containing a helipad and facilities. B: a prominent high, steep peak. | K36: 대한민국 국가유산청 · 독도 천연보호구역 https://www.heritage.go.kr/heri/cul/culSelectDetail.do?VdkVgwKey=16%2C03360000%2C37&pageNo=1_1_2_0 대한민국 전북교육청 · 독도 사진 자료 https://www.jbe.go.kr/dokdo/assets/sub/picture.html
A37: 920036 | B37: What should be changed in a model that makes Dongdo as pointed as Seodo? | C37: Restore Dongdo’s comparatively level upper area | D37: Make Dongdo higher than Seodo | E37: Remove all of Dongdo’s coastal cliffs | G37: 1 | H37: Represent Dongdo’s comparatively level upper area as well as its coastal cliffs. | I37: Seodo rises steeply; Dongdo has a comparatively level upper area. | J37: Terrain data: Seodo 168.5 m with a steep peak; Dongdo 98.6 m with coastal cliffs and a comparatively level upper area. Model to revise: two identical pointed mountains differing only in height. | K37: 대한민국 국가유산청 · 독도 천연보호구역 https://www.heritage.go.kr/heri/cul/culSelectDetail.do?VdkVgwKey=16%2C03360000%2C37&pageNo=1_1_2_0 대한민국 전북교육청 · 독도 사진 자료 https://www.jbe.go.kr/dokdo/assets/sub/picture.html
A38: 920037 | B38: Does Dokdo’s terrain continue underwater below Dongdo and Seodo? | C38: It ends at sea level | D38: It continues underwater | G38: 2 | H38: Dongdo and Seodo are exposed parts of an underwater volcanic structure. | I38: Dongdo and Seodo are exposed parts of a much larger underwater volcanic structure. | K38: 대한민국 한국해양과학기술원 · 독도 지형 및 지질 https://www.dokdo.re.kr/home/cms/cmsCont.do?cntnts_sn=66
A39: 920038 | B39: The two main islands of Dokdo are exposed parts of what? | C39: A river delta | D39: An underwater volcanic structure | E39: A coral-built island | G39: 2 | H39: The exposed islands belong to a volcanic structure formed underwater. | I39: Dongdo and Seodo are exposed parts of a much larger underwater volcanic structure. | K39: 대한민국 한국해양과학기술원 · 독도 지형 및 지질 https://www.dokdo.re.kr/home/cms/cmsCont.do?cntnts_sn=66
A40: 920039 | B40: From where is the approximately 2,300 m height of Dokdo’s volcanic structure measured? | C40: From sea level to Seodo’s peak | D40: From sea level to Dongdo’s peak | E40: From the submarine base | G40: 3 | H40: About 2,300 m describes the entire structure from its submarine base. | I40: Dongdo and Seodo are exposed parts of a much larger underwater volcanic structure. | J40: Seodo’s elevation above sea level: 168.5 m. The full Dokdo volcanic structure: about 2,300 m from its submarine base. Note the different reference levels. | K40: 대한민국 한국해양과학기술원 · 독도 지형 및 지질 https://www.dokdo.re.kr/home/cms/cmsCont.do?cntnts_sn=66
...

Sheet 이전대조
A1: old ID | B1: new ID | C1: 이전 질문 | D1: 수정 질문 | E1: 기록 정책
A2: 910001 | B2: 920001 | C2: 독도의 두 큰 섬은? | D2: 독도를 이루는 두 큰 섬의 이름은 무엇인가요? | E2: 이전 ID는 회수하고 학습 기록·불빛은 보존. 새 문제의 정답·숙달로 자동 치환하지 않음.
A3: 910002 | B3: 920002 | C3: 동도·서도만 그리면 빠지는 것은? | D3: 독도의 두 큰 섬 주위에는 어떤 땅이 더 있나요? | E3: 이전 ID는 회수하고 학습 기록·불빛은 보존. 새 문제의 정답·숙달로 자동 치환하지 않음.
A4: 910003 | B4: 920003 | C4: 자료의 89개는 무엇을 센 수일까요? | D4: 독도 안내판에 두 큰 섬만 그렸다면 어떤 땅을 추가해야 하나요? | E4: 이전 ID는 회수하고 학습 기록·불빛은 보존. 새 문제의 정답·숙달로 자동 치환하지 않음.
A5: 910004 | B5: 920004 | C5: 독도를 ‘섬 두 개뿐’이라 소개한 글의 수정은? | D5: 독도를 ‘동도 한 섬의 이름’이라고 쓴 문장을 어떻게 고쳐야 하나요? | E5: 이전 ID는 회수하고 학습 기록·불빛은 보존. 새 문제의 정답·숙달로 자동 치환하지 않음.
A6: 910005 | B6: 920005 | C6: 울릉도에서 독도는 어느 방향일까요? | D6: 독도는 울릉도에서 어느 방향에 있나요? | E6: 이전 ID는 회수하고 학습 기록·불빛은 보존. 새 문제의 정답·숙달로 자동 치환하지 않음.
A7: 910006 | B7: 920006 | C7: 울릉도와 독도의 관계는? | D7: 울릉도와 독도 사이의 거리는 약 얼마인가요? | E7: 이전 ID는 회수하고 학습 기록·불빛은 보존. 새 문제의 정답·숙달로 자동 치환하지 않음.
A8: 910007 | B8: 920007 | C8: 주어진 거리에서 독도에 더 가까운 곳은? | D8: 거리표에서 독도에 더 가까운 곳은 어디인가요? | E8: 이전 ID는 회수하고 학습 기록·불빛은 보존. 새 문제의 정답·숙달로 자동 치환하지 않음.
A9: 910008 | B9: 920008 | C9: 이 거리 표만으로 뒷받침되는 말은? | D9: 독도에서 울릉도까지는 오키섬까지보다 몇 km 더 가까운가요? | E9: 이전 ID는 회수하고 학습 기록·불빛은 보존. 새 문제의 정답·숙달로 자동 치환하지 않음.
A10: 910009 | B10: 920009 | C10: 독도의 동쪽 큰 섬 이름은? | D10: 독도의 동쪽에 있는 큰 섬은 무엇인가요? | E10: 이전 ID는 회수하고 학습 기록·불빛은 보존. 새 문제의 정답·숙달로 자동 치환하지 않음.
A11: 910010 | B11: 920010 | C11: 서도 이름의 ‘서’와 연결되는 방향은? | D11: 독도의 서쪽 큰 섬을 지도에 표시하려면 어떤 이름을 쓰나요? | E11: 이전 ID는 회수하고 학습 기록·불빛은 보존. 새 문제의 정답·숙달로 자동 치환하지 않음.
A12: 910011 | B12: 920011 | C12: 주어진 방향도에서 동도는 서도의 어느 쪽인가요? | D12: 위치표에서 A에 넣을 섬 이름은 무엇인가요? | E12: 이전 ID는 회수하고 학습 기록·불빛은 보존. 새 문제의 정답·숙달로 자동 치환하지 않음.
A13: 910012 | B13: 920012 | C13: 지도를 돌려 동도가 왼쪽에 보이면? | D13: 동쪽 화살표가 왼쪽을 가리키는 위치표에서 동도는 어느 쪽에 놓이나요? | E13: 이전 ID는 회수하고 학습 기록·불빛은 보존. 새 문제의 정답·숙달로 자동 치환하지 않음.
... A241: 910240 | B241: 920240 | C241: 여러 자료로 독도를 설명할 때 지킬 기준은? | D241: 독도 소개문에 넣을 설명으로 사실에 맞는 것은 무엇인가요? | E241: 이전 ID는 회수하고 학습 기록·불빛은 보존. 새 문제의 정답·숙달로 자동 치환하지 않음.

Sheet 출처30
A1: source ID | B1: 국가·공개 기관 | C1: 원문 URL | D1: 근거 위치 | E1: 공개 국가 | F1: 확인 방식·한계 | G1: 출처 역할 | H1: originalCreator | I1: checked
